Workbook

Sheet DONE - BTC Boosted Program
A1: Date | B1: AUM | C1: Gross Performance (%) | D1: Gross Performance (BTC) | E1: Net Performance | F1: Yearly APY | G1: Comments | I1: Investors | J1: Fees | K1: 45640 | L1: 45658 | M1: 45689 | N1: 45717 | O1: 45748 | P1: 45763
A2: 45640 | B2: 11.5681 | C2: 1 | G2: Création du fond | I2: Indigo | J2: 0 | K2: 0 | L2: =K2*$C$3*1+K2+(K3*$C$3*0.15)+(K4*$C$3*0.1)+(K5*$C$3*0.1) | M2: =L2*$C$4*1+L2+(L3*$C$4*0.15)+(L4*$C$4*0.1)+(L5*$C$4*0.1) | N2: =M2*$C$5*1+M2+(M3*$C$5*0.15)+(M4*$C$5*0.1)+(M5*$C$5*0.1) | O2: =N2*$C$6*1+N2+(N3*$C$6*0.15)+(N4*$C$6*0.1)+(N5*$C$6*0.1) | P2: =O2*$C$7*1+O2+(O3*$C$7*0.15)+(O4*$C$7*0.1)+(O5*$C$7*0.1)
A3: 45658 | B3: 11.61 | C3: =(B3*$C$2/B2)-100% | D3: =B3-B2 | E3: =C3*0.8 | F3: =C3*12 | I3: Kyle Gulamerian | J3: 0.15 | K3: 2.0336 | L3: =K3*$C$3*0.85+K3 | M3: =L3*$C$4*0.85+L3 | N3: =M3*$C$5*0.85+M3 | O3: =N3*$C$6*0.85+N3 | P3: =O3*$C$7*0.85+O3
A4: 45689 | B4: 11.73 | C4: =(B4*$C$2/B3)-100% | D4: =B4-B3 | E4: =C4*0.8 | F4: =C4*12 | I4: Matthias Reiser | J4: 0.1 | K4: 4.6717 | L4: =K4*$C$3*0.9+K4 | M4: =L4*$C$4*0.9+L4 | N4: =M4*$C$5*0.9+M4 | O4: =N4*$C$6*0.9+N4 | P4: =O4*$C$7*0.9+O4
A5: 45717 | B5: 11.84 | C5: =(B5*$C$2/B4)-100% | D5: =B5-B4 | E5: =C5*0.8 | F5: =C5*12 | I5: Danielle Richetta | J5: 0.1 | K5: 4.8627 | L5: =K5*$C$3*0.9+K5 | M5: =L5*$C$4*0.9+L5 | N5: =M5*$C$5*0.9+M5 | O5: =N5*$C$6*0.9+N5 | P5: =O5*$C$7*0.9+O5
A6: 45747 | B6: 11.95 | C6: =(B6*$C$2/B5)-100% | D6: =B6-B5 | E6: =C6*0.8 | F6: =C6*12 | I6: Total AUM | K6: =SUM(K2:K5) | L6: =SUM(L2:L5) | M6: =SUM(M2:M5) | N6: =SUM(N2:N5) | O6: =SUM(O2:O5) | P6: =SUM(P2:P5)
A7: 45763 | B7: 12.02 | C7: =(B7*$C$2/B6)-100% | D7: =B7-B6 | E7: =C7*0.8 | F7: =C7*12
A8: Closing the fond + transfert the assets in BTC Yield Fund | I8: Indigo | K8: =IFERROR(K2/K$6,"") | L8: =IFERROR(L2/L$6,"") | M8: =IFERROR(M2/M$6,"") | N8: =IFERROR(N2/N$6,"") | O8: =IFERROR(O2/O$6,"") | P8: =IFERROR(P2/P$6,"")
I9: Kyle | K9: =IFERROR(K3/K$6,"") | L9: =IFERROR(L3/L$6,"") | M9: =IFERROR(M3/M$6,"") | N9: =IFERROR(N3/N$6,"") | O9: =IFERROR(O3/O$6,"") | P9: =IFERROR(P3/P$6,"")
A10: Total | B10: 4 Months | C10: =(B7-B2)/B2 | D10: =B7-B2 | E10: =C10*0.8 | F10: =E10/4*12 | I10: Mathias | K10: =IFERROR(K4/K$6,"") | L10: =IFERROR(L4/L$6,"") | M10: =IFERROR(M4/M$6,"") | N10: =IFERROR(N4/N$6,"") | O10: =IFERROR(O4/O$6,"") | P10: =IFERROR(P4/P$6,"")
I11: Danielle Richetta | K11: =IFERROR(K5/K$6,"") | L11: =IFERROR(L5/L$6,"") | M11: =IFERROR(M5/M$6,"") | N11: =IFERROR(N5/N$6,"") | O11: =IFERROR(O5/O$6,"") | P11: =IFERROR(P5/P$6,"")
I12: Total AUM | K12: =SUM(K8:K11) | L12: =SUM(L8:L11) | M12: =SUM(M8:M11) | N12: =SUM(N8:N11) | O12: =SUM(O8:O11) | P12: =SUM(P8:P11)

Sheet DONE - BTC TAC Program
A1: Date | B1: AUM | C1: Gross Performance (%) | D1: Gross Performance (BTC) | E1: Net Performance | F1: Yearly APY | G1: Comments | I1: Investors | J1: Fees | K1: 45748 | L1: 45778 | M1: 45809 | N1: 45839 | O1: 45849
A2: 45748 | B2: 11.4434 | C2: 1 | G2: Création du fond : Invest : Victoria : 0.1492 Nathanaël : 0.4483 Blondish : 4.1210 | I2: Indigo | J2: 0 | K2: 0 | L2: =K2*$C$3*1+K2+(K3*$C$3*$J$3)+(K4*$C$3*$J$4)+(K5*$C$3*$J$5)+(K6*$C$3*$J$6) | M2: =L2*$C$4*1+L2+(L3*$C$4*$J$3)+(L4*$C$4*$J$4)+(L5*$C$4*$J$5)+(L6*$C$4*$J$6) | N2: =M2*$C$5*1+M2+(M3*$C$5*$J$3)+(M4*$C$5*$J$4)+(M5*$C$5*$J$5)+(M6*$C$5*$J$6) | O2: =N2*$C$5*1+N2+(N3*$C$5*$J$3)+(N4*$C$5*$J$4)+(N5*$C$5*$J$5)+(N6*$C$5*$J$6)
A3: 45778 | B3: 11.394 | C3: =(B3*$C$2/B2)-100% | D3: =B3-B2 | E3: =C3*0.8 | F3: =C3*12 | I3: Victoria Pariente-Cohen | J3: 0 | K3: 0.1492 | L3: =K3*$C$3*(1-$J3)+K3 | M3: =L3*$C$4*(1-$J3)+L3 | N3: =M3*$C$5*(1-$J3)+M3 | O3: =N3*$C$6*(1-$J3)+N3
A4: 45807 | B4: 11.3943 | C4: =(B4*$C$2/B3)-100% | D4: =B4-B3 | E4: =C4*0.8 | F4: =C4*12 | I4: Nathanaël Cohen | J4: 0 | K4: 0.4483 | L4: =K4*$C$3*(1-$J4)+K4 | M4: =L4*$C$4*(1-$J4)+L4 | N4: =M4*$C$5*(1-$J4)+M4 | O4: =N4*$C$6*(1-$J4)+N4
A5: 45838 | B5: 11.3943 | C5: =(B5*$C$2/B4)-100% | D5: =B5-B4 | E5: =C5*0.8 | F5: =C5*12 | I5: Thomas Puech | J5: 0 | K5: 6.7249 | L5: =K5*$C$3*(1-$J5)+K5 | M5: =L5*$C$4*(1-$J5)+L5 | N5: =M5*$C$5*(1-$J5)+M5 | O5: =N5*$C$6*(1-$J5)+N5
A6: 45849 | B6: 11.384 | C6: =(B6*$C$2/B5)-100% | D6: =B6-B5 | E6: =C6*0.8 | F6: =C6*12 | G6: End of fund and transfert to BTC Yield Fund | I6: Blondish | J6: 0 | K6: 4.121 | L6: =K6*$C$3*(1-$J6)+K6 | M6: =L6*$C$4*(1-$J6)+L6 | N6: =M6*$C$5*(1-$J6)+M6 | O6: =N6*$C$6*(1-$J6)+N6
A7: Closing the fond + transfert the assets in BTC Yield Fund | I7: Total | K7: =SUM(K2:K6) | L7: =SUM(L2:L6) | M7: =SUM(M2:M6) | N7: =SUM(N2:N6) | O7: =SUM(O2:O6)
A9: Total | B9: 3.5 Months | C9: =(B6-B2)/B2 | D9: =B6-B2 | E9: =C9*0.8 | F9: =E9/3.5*12 | I9: Indigo | K9: =IFERROR(K2/K$7,"") | L9: =IFERROR(L2/L$7,"") | M9: =IFERROR(M2/M$7,"") | N9: =IFERROR(N2/N$7,"") | O9: =IFERROR(O2/O$7,"")
I10: Maman | K10: =IFERROR(K3/K$7,"") | L10: =IFERROR(L3/L$7,"") | M10: =IFERROR(M3/M$7,"") | N10: =IFERROR(N3/N$7,"") | O10: =IFERROR(O3/O$7,"")
I11: Nathanael | K11: =IFERROR(K4/K$7,"") | L11: =IFERROR(L4/L$7,"") | M11: =IFERROR(M4/M$7,"") | N11: =IFERROR(N4/N$7,"") | O11: =IFERROR(O4/O$7,"")
I12: Thomas | K12: =IFERROR(K5/K$7,"") | L12: =IFERROR(L5/L$7,"") | M12: =IFERROR(M5/M$7,"") | N12: =IFERROR(N5/N$7,"") | O12: =IFERROR(O5/O$7,"")
I13: Vivie | K13: =IFERROR(K6/K$7,"") | L13: =IFERROR(L6/L$7,"") | M13: =IFERROR(M6/M$7,"") | N13: =IFERROR(N6/N$7,"") | O13: =IFERROR(O6/O$7,"")
I14: Total AUM | K14: =SUM(K9:K13) | L14: =SUM(L9:L13) | M14: =SUM(M9:M13) | N14: =SUM(N9:N13) | O14: =SUM(O9:O13)

Sheet Done - ETH TAC Program
A1: Date | B1: AUM | C1: Gross Performance (%) | D1: Gross Performance (ETH) | E1: Net Performance | F1: Yearly APY | G1: Comments | I1: Investors | J1: Fees | K1: 45505 | L1: 45536 | M1: 45566 | N1: 45589 | O1: 45597 | P1: 45627 | Q1: 45658 | R1: 45689 | S1: 45717 | T1: 45748 | U1: 45778 | V1: 45809 | W1: 45839 | X1: 45849
A2: 45474 | B2: 61.5 | C2: 1 | G2: Creation du fond | I2: Indigo Fees | J2: 0 | K2: =B2*C3*0.2 | L2: =K2*$C$4*1+K2+(K3*$C$4*0.2) | M2: =L2*$C$5*1+L2+(L3*$C$5*0.2) | N2: =M2*$C$7*1+M2+(M3*$C$7*0.2) | O2: =N2*$C$9*1+N2+(N3*$C$9*0.2) | P2: =O2*$C$10*1+O2+(O3*$C$10*0.2) | Q2: =P2*$C$11*1+P2+(P3*$C$11*0.2) | R2: =Q2*$C$12*1+Q2+(Q3*$C$12*0.2) | S2: =R2*$C$13*1+R2+(R3*$C$13*0.2) | T2: =S2*$C$15*1+S2+(S3*$C$15*0.2) | U2: =T2*$C$17*1+T2+(T3*$C$17*0.2) | V2: =U2*$C$18*1+U2+(U3*$C$18*0.2) | W2: =V2*$C$19*1+V2+(V3*$C$19*0.2) | X2: =W2*$C$20*1+W2
A3: 45505 | B3: 62.27 | C3: =(B3*$C$2/B2)-100% | D3: =B3-B2 | E3: =C3*0.8 | F3: =C3*12 | I3: Jose Molla | J3: 0.2 | K3: =B2*C3*0.8+B2 | L3: =K3*$C$4*0.8+K3 | M3: =L3*$C$5*0.8+L3 | N3: =M3*$C$7*0.8+M3 | O3: =N3*$C$9*0.8+N3 | P3: =O3*$C$10*0.8+O3 | Q3: =P3*$C$11*0.8+P3 | R3: =Q3*$C$12*0.8+Q3 | S3: =R3*$C$13*0.8+R3 | T3: =S3*$C$15*0.8+S3 | U3: =T3*$C$17*0.8+T3 | V3: =U3*$C$18*0.8+U3 | W3: =V3*$C$19*0.8+V3 | X3: =W3*$C$20+W3
A4: 45537 | B4: 62.82 | C4: =(B4*$C$2/B3)-100% | D4: =B4-B3 | E4: =C4*0.8 | F4: =C4*12 | I4: Nathanael Cohen | J4: 0 | K4: 0 | L4: 0 | M4: 17 | N4: =M4*$C$7+M4 | O4: =N4*$C$9+N4 | P4: =O4*$C$10+O4 | Q4: =P4*$C$11+P4 | R4: =Q4*$C$12+Q4 | S4: =R4*$C$13+R4+4.608 | T4: =S4*$C$15+S4+5.226 | U4: =T4*$C$17+T4 | V4: =U4*$C$18+U4 | W4: =V4*$C$19+V4 | X4: =W4*$C$20+W4
A5: 45566 | B5: 63.33 | C5: =(B5/B4)-100% | D5: =B5-B4 | E5: =C5*0.8 | F5: =C5*12 | I5: Blondish | J5: 0 | K5: 0 | L5: 0 | M5: 0 | N5: 120 | O5: =N5*$C$9+N5 | P5: =O5*$C$10+O5 | Q5: =P5*$C$11+P5 | R5: =Q5*$C$12+Q5 | S5: =R5*$C$13+R5 | T5: =S5*$C$15+S5 | U5: =T5*$C$17+T5 | V5: =U5*$C$18+U5 | W5: =V5*$C$19+V5 | X5: =W5*$C$20+W5
A6: 45565 | B6: =17+B5 | C6: 1 | G6: Entrée de Nathanael avec 17 ETH | I6: Total AUM | K6: =SUM(K2:K5) | L6: =SUM(L2:L5) | M6: =SUM(M2:M5) | N6: =SUM(N2:N5) | O6: =SUM(O2:O5) | P6: =SUM(P2:P5) | Q6: =SUM(Q2:Q5) | R6: =SUM(R2:R5) | ... X6: =SUM(X2:X5)
A7: 45589 | B7: 80.72 | C7: =(B7/B6)-100% | D7: =B7-B6 | E7: =C7*0.8 | F7: =C7*12
A8: 45590 | B8: =B7+120 | C8: 1 | G8: Entrée de Blondish avec 120 ETH | I8: Indigo | K8: =IFERROR(K2/K$6,"") | L8: =IFERROR(L2/L$6,"") | M8: =IFERROR(M2/M$6,"") | N8: =IFERROR(N2/N$6,"") | O8: =IFERROR(O2/O$6,"") | P8: =IFERROR(P2/P$6,"") | Q8: =IFERROR(Q2/Q$6,"") | R8: =IFERROR(R2/R$6,"") | ... X8: =IFERROR(X2/X$6,"")
A9: 45597 | B9: 200.72 | C9: =(B9/B8)-100% | D9: =B9-B8 | E9: =C9*0.8 | F9: =C9*12 | I9: Jose | K9: =IFERROR(K3/K$6,"") | L9: =IFERROR(L3/L$6,"") | M9: =IFERROR(M3/M$6,"") | N9: =IFERROR(N3/N$6,"") | O9: =IFERROR(O3/O$6,"") | P9: =IFERROR(P3/P$6,"") | Q9: =IFERROR(Q3/Q$6,"") | R9: =IFERROR(R3/R$6,"") | ... X9: =IFERROR(X3/X$6,"")
A10: 45627 | B10: 200.72 | C10: =(B10/B9)-100% | D10: =B10-B9 | E10: =C10*0.8 | F10: =C10*12 | I10: Nathanael | K10: =IFERROR(K4/K$6,"") | L10: =IFERROR(L4/L$6,"") | M10: =IFERROR(M4/M$6,"") | N10: =IFERROR(N4/N$6,"") | O10: =IFERROR(O4/O$6,"") | P10: =IFERROR(P4/P$6,"") | Q10: =IFERROR(Q4/Q$6,"") | R10: =IFERROR(R4/R$6,"") | ... X10: =IFERROR(X4/X$6,"")
A11: 45658 | B11: 200.72 | C11: =(B11/B10)-100% | D11: =B11-B10 | E11: =C11*0.8 | F11: =C11*12 | I11: Blondish | K11: =IFERROR(K5/K$6,"") | L11: =IFERROR(L5/L$6,"") | M11: =IFERROR(M5/M$6,"") | N11: =IFERROR(N5/N$6,"") | O11: =IFERROR(O5/O$6,"") | P11: =IFERROR(P5/P$6,"") | Q11: =IFERROR(Q5/Q$6,"") | R11: =IFERROR(R5/R$6,"") | ... X11: =IFERROR(X5/X$6,"")
A12: 45689 | B12: 201.847 | C12: =(B12/B11)-100% | D12: =B12-B11 | E12: =C12*0.8 | F12: =C12*12 | I12: Total AUM | K12: =SUM(K8:K11) | L12: =SUM(L8:L11) | M12: =SUM(M8:M11) | N12: =SUM(N8:N11) | O12: =SUM(O8:O11) | P12: =SUM(P8:P11) | Q12: =SUM(Q8:Q11) | R12: =SUM(R8:R11) | ... X12: =SUM(X8:X11)
A13: 45717 | B13: 204.35 | C13: =(B13/B12)-100% | D13: =B13-B12 | E13: =C13*0.8 | F13: =C13*12
A14: 45717 | B14: =B13+4.608 | C14: 1 | G14: Top up de Nathanael avec 4.608 ETH | W14: 8.404 | X14: Refund Tea-Fi hack
A15: 45747 | B15: 209.553 | C15: =(B15/B14)-100% | D15: =B15-B14 | E15: =C15*0.8 | F15: =C15*12
A16: 45748 | B16: =B15+5.226 | C16: 1 | G16: Top up de Nathanael avec 5.226 ETH
A17: 45778 | B17: 217.3475 | C17: =(B17/B16)-100% | D17: =B17-B16 | E17: =C17*0.8 | F17: =C17*12
A18: 45807 | B18: 217.8624 | C18: =(B18/B17)-100% | D18: =B18-B17 | E18: =C18*0.8 | F18: =C18*12
A19: 45838 | B19: 218.3559 | C19: =(B19/B18)-100% | D19: =B19-B18 | E19: =C19*0.8 | F19: =C19*12
A20: 45849 | B20: =209.85+0.14 | C20: =(B20/B19)-100% | D20: =B20-B19 | E20: =C20*0.8 | F20: =C20*12 | G20: End of fund and transfert to ETH Yield Fund
A21: Closing the fond + transfert the assets in ETH Yield Fund
A23: Total | B23: 11.5 Months | C23: =(B20-(B2+17+120+4.608+5.226))/(B2+17+120+4.608+5.226) | D23: =B20-(B2+17+120+4.608+5.226) | E23: =C23*0.8 | F23: =E23/11.5*12
A25: Refund Tea-Fi hack for 8.404 ETH on 03/11/2025
A26: Indigo | B26: 0.0042762316 | C26: =B26*$C$31
A27: Jose | B27: 0.29823391 | C27: =B27*$C$31
A28: Nathanael | B28: 0.12705205 | C28: =B28*$C$31
A29: Blondish | B29: 0.57043781 | C29: =B29*$C$31
A31: Total | B31: =SUM(B26:B29) | C31: 8.404

Sheet Investments
A1: Investment Date | B1: Investor Name | C1: Currency | D1: Amount | E1: Intro Broker Name | F1: IB Percentage | G1: Fee Percentage | H1: Account Type | I1: Transaction Type | J1: Reference ID
A2: 45455 | B2: Jose Molla | C2: BTC | D2: 2.723
A3: 45455 | B3: Jose Molla | C3: ETH TAC | D3: 52.4
A4: 45481 | B4: Jose Molla | C4: BTC | D4: 0.745
A5: 45481 | B5: Jose Molla | C5: ETH TAC | D5: 9.1
A6: 45525 | B6: Kyle Gulamerian | C6: BTC | D6: 0.01
A7: 45525 | B7: Kyle Gulamerian | C7: BTC | D7: 1.99
A8: 45566 | B8: Matthias Reiser | C8: BTC | D8: 4.62
A9: 45566 | B9: Thomas Puech | C9: BTC | D9: 6.5193
A10: 45566 | B10: Danielle Richetta | C10: BTC | D10: 5.2
A11: 45566 | B11: Nathanaël Cohen | C11: ETH TAC | D11: 17
A12: 45589 | B12: Blondish | C12: ETH TAC | D12: 120
A13: 45605 | B13: Danielle Richetta | C13: BTC | D13: -0.27
... A26: 45748 | B26: Thomas Puech | C26: BTC | D26: -6.7249
A27: 45748 | B27: Thomas Puech | C27: BTC TAC | D27: =6.7249
A28: 45763 | B28: Kyle Gulamerian | C28: BTC | D28: 2.101
A29: 45763 | B29: Matthias Reiser | C29: BTC | D29: 4.8357
A30: 45763 | B30: Danielle Richetta | C30: BTC | D30: 5.0335
A31: 45763 | B31: Kyle Gulamerian | C31: BTC Boost | D31: -2.101
A32: 45763 | B32: Matthias Reiser | C32: BTC Boost | D32: -4.8357
A33: 45763 | B33: Danielle Richetta | C33: BTC Boost | D33: -5.0335
A34: 45763 | B34: INDIGO Fees | C34: BTC | D34: 0.0498
A35: 45763 | B35: INDIGO Fees | C35: BTC Boost | D35: -0.0498
A36: 45790 | B36: Kyle Gulamerian | C36: BTC | D36: =-0.1078-2.0023
A37: 45803 | B37: Babak Eftekhari | C37: ETH | D37: 27.01
A38: 45803 | B38: INDIGO DIGITAL ASSET FUND LP | C38: ETH | D38: 175
A39: 45809 | B39: Nathanaël Cohen | C39: ETH | D39: 3.0466
A40: 45807 | B40: Babak Eftekhari | C40: ETH | D40: 32.25
A41: 45809 | B41: danielle Richetta | C41: BTC | D41: -0.13
A42: 45819 | B42: Kabbaj | C42: BTC | D42: 2 | E42: Hicham.kabbaj@sgtm-maroc.com
A43: 45824 | B43: Babak Eftekhari | C43: USDT | D43: =134026.75+1700
A44: 45839 | B44: Nathanaël Cohen | C44: ETH | D44: 2
A45: 45849 | B45: Jose Molla | C45: ETH TAC | D45: -62.6261
A46: 45849 | B46: Nathanaël Cohen | C46: ETH TAC | D46: -26.6797
A47: 45849 | B47: Blondish | C47: ETH TAC | D47: -119.7862
A48: 45849 | B48: Indigo Fees | C48: ETH TAC | D48: -0.898
A49: 45849 | B49: Jose Molla | C49: ETH | D49: 62.6261
A50: 45849 | B50: Nathanaël Cohen | C50: ETH | D50: 26.6797
A51: 45849 | B51: Blondish | C51: ETH | D51: 119.7862
A52: 45849 | B52: Indigo Fees | C52: ETH | D52: 0.898
...

Sheet BTC Yield Fund
A1: AUM Before | D1: 0 | E1: 3.49 | F1: 3.5 | G1: 5.51 | H1: 5.54 | I1: 21.99 | J1: =22.02 | K1: 21.84 | L1: 21.88 | M1: =L3 | N1: 10.24 | O1: 10.3 | P1: 10.34 | Q1: 10.38 | R1: 3.68 | S1: 15.76 | T1: 15.78 | U1: =13.69+0.044 | V1: 13.6446 | W1: 15.6577 | X1: 15.7177 | Y1: 28.1007 | Z1: 30.2177 | AA1: 29.9777 | AB1: 30.66 | AC1: 30.565 | AD1: 31.49 | AE1: 31.6 | AF1: 31.62 | AG1: 32.14 | AH1: 32.21 | AI1: 32.23 | AJ1: 31.55 | AK1: 32.06 | AL1: 35.36 | AM1: 36.92 | AN1: 41.331 | AO1: 42.58 | AP1: 43.73 | AQ1: 44.4 | AR1: 45.58 | AS1: 40.5905 | AT1: 40.5905 | AU1: 32.82 | AV1: 31.61 | AW1: 32.36 | AX1: 36.24 | AY1: 32.25 | AZ1: 32.4 | BA1: 32.4 | BB1: 33.07 | BC1: 33.25 | BD1: 42.016 | BE1: 38.39 | BF1: 38.541
A2: Top Up / Withdrawals | D2: =SUMIFS(Investments!$D:$D,Investments!$C:$C,"BTC",Investments!$A:$A,D$8) | E2: =SUMIFS(Investments!$D:$D,Investments!$C:$C,"BTC",Investments!$A:$A,E$8) | F2: =SUMIFS(Investments!$D:$D,Investments!$C:$C,"BTC",Investments!$A:$A,F$8) | G2: =SUMIFS(Investments!$D:$D,Investments!$C:$C,"BTC",Investments!$A:$A,G$8) | H2: =SUMIFS(Investments!$D:$D,Investments!$C:$C,"BTC",Investments!$A:$A,H$8) | I2: =SUMIFS(Investments!$D:$D,Investments!$C:$C,"BTC",Investments!$A:$A,I$8) | J2: =SUMIFS(Investments!$D:$D,Investments!$C:$C,"BTC",Investments!$A:$A,J$8) | K2: =SUMIFS(Investments!$D:$D,Investments!$C:$C,"BTC",Investments!$A:$A,K$8) | ... BF2: =SUMIFS(Investments!$D:$D,Investments!$C:$C,"BTC",Investments!$A:$A,BF$8)
A3: AUM After | D3: 3.468 | E3: 3.49 | F3: =3.5+2 | G3: =G1 | H3: =H1+4.62+6.5193+5.2 | I3: =I1 | J3: =J1-0.27 | K3: =K1 | L3: =21.88-0.124 | M3: =21.88-0.124-11.5681 | N3: =N1 | O3: =O1 | P3: =P1 | Q3: =Q1-6.7249 | R3: =R1+12.02 | S3: =S1 | T3: =T1+T2 | U3: =U1-0.13 | V3: =V1+2 | W3: =W1 | X3: =X1+11.384+0.9914 | Y3: =Y1+2.115364 | Z3: =Z1-0.26 | AA3: =AA1+0.6 | AB3: =AB1-0.11 | AC3: =AC1+0.9102 | AD3: =AD1 | AE3: =AE1 | AF3: =AF1+0.4395 | AG3: =AG1+0.062 | AH3: =AH1 | AI3: =AI1-0.283-0.4408 | AJ3: =AJ1+0.4867 | AK3: =AK1+3.3 | AL3: =AL1+1+0.548 | AM3: =AM1+1+3.411 | AN3: =AN1+1.2 | AO3: =AO1+1.1 | AP3: =AP1+0.657 | AQ3: =AQ1+1.17 | AR3: =AR1-4.9895 | AS3: =AS1 | AT3: =AS1-7.7852 | AU3: =AU1-3.4221+2.1577 | AV3: =AV1+0.622+0.1135766 | AW3: =AW1+3.9998-0.12 | AX3: =AX1-3.99 | AY3: =AY1+0.14207 | AZ3: =AZ1 | BA3: =BA1+0.60672 | BB3: =BB1+BB2 | BC3: =BC1+BC2 | BD3: =BD1+BD2 | BE3: =BE1+BE2 | BF3: =BF1+BF2
A4: Gross Performance | E4: =(E3-D3)/D3 | F4: =(F1-E3)/E3 | G4: =(G1-F3)/F3 | H4: =(H1/G1)-100% | I4: =(I1/H3)-100% | J4: =(J1/I1)-100% | K4: =(K1/J3)-100% | L4: =(L1/K1)-100% | N4: =(N1/M3)-100% | O4: =(O1/N1)-100% | P4: =(P1/O1)-100% | Q4: =(Q1/P1)-100% | R4: =(R1-Q3)/Q3 | S4: =(S1/R3)-100% | T4: =(T1/S1)-100% | U4: =(U1-T3)/T3 | V4: =(V1/U3)-100% | W4: =(W1/V3)-100% | X4: =(X1/W1)-100% | Y4: =(Y1/X3)-100% | Z4: =(Z1/Y3)-100% | AA4: =(AA1/Z3)-100% | AB4: =(AB1/AA3)-100% | AC4: =(AC1/AB3)-100% | AD4: =(AD1/AC3)-100% | AE4: =(AE1/AD1)-100% | AF4: =(AF1/AE1)-100% | AG4: =(AG1/AF3)-100% | AH4: =(AH1/AG3)-100% | AI4: =(AI1/AH1)-100% | AJ4: =(AJ1/AI3)-100% | AK4: =(AK1/AJ3)-100% | AL4: =(AL1/AK3)-100% | AM4: =(AM1/AL3)-100% | AN4: =(AN1/AM3)-100% | AO4: =(AO1/AN3)-100% | AP4: =(AP1/AO3)-100% | AQ4: =(AQ1/AP3)-100% | ... AS4: =(AS1/AR3)-100% | AT4: =(AT1/AS1)-100% | AU4: =(AU1/AT3)-100% | AV4: =(AV1/AU3)-100% | AW4: =(AW1/AV3)-100% | AX4: =(AX1/AW3)-100% | AY4: =(AY1/AX3)-100% | AZ4: =(AZ1/AY3)-100% | BA4: =(BA1/AZ1)-100% | BB4: =(BB1-BA3)/BA3 | BC4: =(BC1-BB3)/BB3 | BD4: =(BD1-BC3)/BC3 | BE4: =(BE1-BD3)/BD3 | BF4: =(BF1-BE3)/BE3
A5: Net Performance | E5: =E4*0.8 | F5: =F4*0.8 | G5: =G4*0.8 | H5: =H4*0.8 | I5: =I4*0.8 | J5: =J4*0.8 | K5: =K4*0.8 | L5: =L4*0.8 | N5: =N4*0.8 | O5: =O4*0.8 | P5: =P4*0.8 | Q5: =Q4*0.8 | R5: =R4*0.8 | S5: =S4*0.8 | T5: =T4*0.8 | U5: =U4*0.8 | ... BF5: =BF4*0.8
A6: Yearly APY | E6: =E4*12 | F6: =F4*12 | G6: =G4*12 | H6: =H4*12 | I6: =I4*12 | J6: =J4*12 | K6: =K4*12 | L6: =L4*12 | N6: =N4*12 | O6: =O4*12 | P6: =P4*12 | Q6: =Q4*12 | R6: =R4*12 | S6: =S4*12 | T6: =T4*12 | U6: =U4*12 | ... BF6: =BF4*12
A7: Comments | F7: Invest of Kyle with 2 BTC | H7: Invest of Mathias / Thomas / Daniel with 16.3393 BTC | J7: Withdraw 0.27 from Danielle | L7: Withdraw 0.124 from Danielle | M7: Kyle / Mathias / Danielle go to Boosted Program with 11.5681 BTC | Q7: Thomas go to TAC Program with 6.7249 BTC | R7: Transfert of 12.02 BTC from boosted program for Kyle Gulamerian / Matthias Reiser / Danielle Richetta | T7: Withdraw 0.1078 BTC from Kyle Withdraw 2.0023 BTC from Kyle (all his account) | U7: +0.044 BTC for Gas Fees that has been forgoten Withdraw 0.13 from Danielle Richetta | V7: Kabbaj deposit 2 BTC | X7: Top Up from Kabbaj : 0.9914 BTC Transfert from TAC Program Victoria :0.1484 BTC Nathanael Cohen : 0.4460 BTC Thomas Puech : 6.69 BTC Blondish : 4.0996 BTC | Y7: oliver loisel : 2.115364 BTC | Z7: Withdrawal Danielle Richetta - 0.26 BTC | AA7: Kabbaj : 0.6 BTC | AB7: Withdrawal Danielle Richetta - 0.11 BTC | AC7: Top Up Kabbaj : 0.9102 BTC | AF7: Top Up Paul Johnson: 0.4395 BTC | AG7: Jose Molla BTC 0.062 | AI7: Withdrawal Danielle Richetta - 0.283 BTC Paul Johnson -0.4408 (OUT) | AJ7: Jose Molla BTC 0.4867 | AK7: Sam Johnson BTC 3.30 | AL7: Sam Johnson BTC 1 Jose Molla BTC 0.548 | AM7: Nath & Thomas BTC 1.00 Vivie & Liana BTC 3.411 | AN7: Sam Johnson BTC 1.2 | AO7: Sam Johnson BTC 1.1 | AP7: Thomas Puech : 0.657 BTC | AQ7: Sam Johnson BTC 1.17 | AR7: Matthias Reiser out | AT7: Sam Johnson BTC -7.7852 | AU7: Vivie & Liana - Out -3.4221 Kabbaj BTC 2.1577 | AV7: Nick Smits van Oyen BTC 0.622 Thomas Puech BTC 0.1135766 | AW7: Kyle Gulamerian BTC 3.9998 Danielle Richetta BTC -0.12 | AX7: Kyle Gulamerian BTC -3.99 | AY7: Thomas Puech BTC 0.14207 | BA7: Thomas Puech BTC 0.60672 | BB7: NSVO Holdings BTC 0.1773 | BC7: Jose Molla BTC 2.766 ALOK PAVAN BATRA BTC 6.00 | BD7: Thomas Puech BTC 0.656 Danielle Richetta BTC -4.30 | BE7: Thomas Puech BTC 0.15103283 | BF7: Thomas Puech BTC 0.15103284
A8: Investors | B8: Fees | C8: IB | D8: 45474 | E8: 45505 | F8: 45525 | G8: 45536 | H8: 45566 | I8: 45597 | J8: 45605 | K8: 45627 | L8: 45640 | M8: 45641 | N8: 45658 | O8: 45689 | P8: 45717 | Q8: 45748 | R8: 45763 | S8: 45778 | T8: 45790 | U8: 45809 | V8: 45819 | W8: 45839 | X8: 45849 | Y8: 45862 | Z8: 45863 | AA8: 45869 | AB8: 45889 | AC8: 45894 | AD8: 45901 | AE8: 45930 | AF8: 45933 | AG8: 45953 | AH8: 45961 | AI8: 45966 | AJ8: 45969 | AK8: 45978 | AL8: 45986 | AM8: 45988 | AN8: 45991 | AO8: 45999 | AP8: 46000 | AQ8: 46006 | AR8: 46014 | AS8: 46023 | AT8: 46024 | AU8: 46027 | AV8: 46035 | AW8: 46041 | AX8: 46045 | AY8: 46052 | AZ8: 46054 | BA8: 46056 | BB8: 46059 | BC8: 46065 | BD8: 46066 | BE8: 46077 | BF8: 46081
A9: Indigo Fees | B9: 0 | E9: =D3*E4*$B$10 | F9: =E9*$F$4*1+E9+(E10*$F$4*$B$10) | G9: =F9*$G$4*1+F9+(F10*$G$4*$B$10)+(F11*$G$4*$B$11) | H9: =G9*$H$4*1+G9+(G10*$H$4*$B$10)+(G11*$H$4*$B$11) | I9: =H9*$I$4*1+H9+(H10*$I$4*$B$10)+(H11*$I$4*$B$11)+(H12*$I$4*$B$12)+(H14*$I$4*$B$14) | J9: =I9*$J$4*1+I9+(I10*$J$4*$B$10)+(I11*$J$4*$B$11)+(I12*$J$4*$B$12)+(I14*$J$4*$B$14) | K9: =J9*$K$4*1+J9+(J10*$K$4*$B$10)+(J11*$K$4*$B$11)+(J12*$K$4*$B$12)+(J14*$K$4*$B$14) | L9: =K9*$L$4*1+K9+(K10*$L$4*$B$10)+(K11*$L$4*$B$11)+(K12*$L$4*$B$12)+(K14*$L$4*$B$14) | M9: =L9+L11+L12+L14-2.0336-4.6717-4.8627 | N9: =M9*$N$4*1+M9+(M10*$N$4*$B$10)+(M11*$N$4*$B$11)+(M12*$N$4*$B$12)+(M14*$N$4*$B$14) | O9: =N9*$O$4*1+N9+(N10*$O$4*$B$10)+(N11*$O$4*$B$11)+(N12*$O$4*$B$12)+(N14*$O$4*$B$14) | P9: =O9*$P$4*1+O9+(O10*$P$4*$B$10)+(O11*$P$4*$B$11)+(O12*$P$4*$B$12)+(O14*$P$4*$B$14) | Q9: =P9*$Q$4*1+P9+(P10*$Q$4*$B$10)+(P11*$Q$4*$B$11)+(P12*$Q$4*$B$12)+(P14*$Q$4*$B$14)+(P13*$Q$4*(1-$B13)+P13)-6.7249 | R9: =Q9*$R$4*1+Q9+(Q10*$R$4*$B$10)+(Q11*$R$4*$B$11)+(Q12*$R$4*$B$12)+(Q14*$R$4*$B$14)+0.0498 | S9: =R9*$S$4*1+R9+(R10*$S$4*$B$10)+(R11*$S$4*$B$11)+(R12*$S$4*$B$12)+(R14*$S$4*$B$14) | T9: =S9*$T$4*1+S9+(S10*$T$4*$B$10)+(S11*$T$4*$B$11)+(S12*$T$4*$B$12)+(S14*$T$4*$B$14)+(S11*$T$4*(1-$B11)+S11)-0.1078-2.0023 | U9: =T9*$U$4*1+T9+(T10*$U$4*$B$10)+(T11*$U$4*$B$11)+(T12*$U$4*$B$12)+(T14*$U$4*$B$14) | V9: =U9*$V$4*1+U9+(U10*$V$4*$B$10)+(U11*$V$4*$B$11)+(U12*$V$4*$B$12)+(U14*$V$4*$B$14) | W9: =V9*$W$4*1+V9+(V10*$W$4*$B$10)+(V11*$W$4*$B$11)+(V12*$W$4*$B$12)+(V14*$W$4*$B$14)+(V15*$W$4*$B$15) | X9: =W9*$X$4*1+W9+(W10*$X$4*$B$10)+(W11*$X$4*$B$11)+(W12*$X$4*$B$12)+(W14*$X$4*$B$14)+(W15*$X$4*$B$15) | Y9: =X9*$Y$4*1+X9+(X10*$Y$4*$B$10)+(X11*$Y$4*$B$11)+(X12*$Y$4*$B$12)+(X13*$Y$4*$B$13)+(X14*$Y$4*$B$14)+(X15*$Y$4*$B$15)+(X16*$Y$4*$B$16)+(X17*$Y$4*$B$17)+(X18*$Y$4*$B$18)+(X19*$Y$4*$B$19) | Z9: =Y9*$Z$4*1+Y9+(Y10*$Z$4*$B$10)+(Y11*$Z$4*$B$11)+(Y12*$Z$4*$B$12)+(Y13*$Z$4*$B$13)+(Y14*$Z$4*$B$14)+(Y15*$Z$4*$B$15)+(Y16*$Z$4*$B$16)+(Y17*$Z$4*$B$17)+(Y18*$Z$4*$B$18)+(Y19*$Z$4*$B$19) | AA9: =Z9*$AA$4*1+Z9+(Z10*$AA$4*$B$10)+(Z11*$AA$4*$B$11)+(Z12*$AA$4*$B$12)+(Z13*$AA$4*$B$13)+(Z14*$AA$4*$B$14)+(Z15*$AA$4*$B$15)+(Z16*$AA$4*$B$16)+(Z17*$AA$4*$B$17)+(Z18*$AA$4*$B$18)+(Z19*$AA$4*$B$19) | AB9: =AA9*$AB$4*1+AA9+(AA10*$AB$4*$B$10)+(AA11*$AB$4*$B$11)+(AA12*$AB$4*$B$12)+(AA13*$AB$4*$B$13)+(AA14*$AB$4*$B$14)+(AA15*$AB$4*$B$15)+(AA16*$AB$4*$B$16)+(AA17*$AB$4*$B$17)+(AA18*$AB$4*$B$18)+(AA19*$AB$4*$B$19) | AC9: =AB9*$AC$4*1+AB9+(AB10*$AC$4*$B$10)+(AB11*$AC$4*$B$11)+(AB12*$AC$4*$B$12)+(AB13*$AC$4*$B$13)+(AB14*$AC$4*$B$14)+(AB15*$AC$4*$B$15)+(AB16*$AC$4*$B$16)+(AB17*$AC$4*$B$17)+(AB18*$AC$4*$B$18)+(AB19*$AC$4*$B$19) | AD9: =AC9*$AD$4*1+AC9+(AC10*$AD$4*$B$10)+(AC11*$AD$4*$B$11)+(AC12*$AD$4*$B$12)+(AC13*$AD$4*$B$13)+(AC14*$AD$4*$B$14)+(AC15*$AD$4*$B$15)+(AC16*$AD$4*$B$16)+(AC17*$AD$4*$B$17)+(AC18*$AD$4*$B$18)+(AC19*$AD$4*$B$19) | AE9: =AD9*$AE$4*1+AD9+(AD10*$AE$4*$B$10)+(AD11*$AE$4*$B$11)+(AD12*$AE$4*$B$12)+(AD13*$AE$4*$B$13)+(AD14*$AE$4*$B$14)+(AD15*$AE$4*$B$15)+(AD16*$AE$4*$B$16)+(AD17*$AE$4*$B$17)+(AD18*$AE$4*$B$18)+(AD19*$AE$4*$B$19) | AF9: =AE9*$AF$4*1+AE9+(AE10*$AF$4*$B$10)+(AE11*$AF$4*$B$11)+(AE12*$AF$4*$B$12)+(AE13*$AF$4*$B$13)+(AE14*$AF$4*$B$14)+(AE15*$AF$4*$B$15)+(AE16*$AF$4*$B$16)+(AE17*$AF$4*$B$17)+(AE18*$AF$4*$B$18)+(AE19*$AF$4*$B$19)+(AE20*$AF$4*$B$20)+(AE21*$AF$4*$B$21) | AG9: =AF9*$AG$4*1+AF9+(AF10*$AG$4*$B$10)+(AF11*$AG$4*$B$11)+(AF12*$AG$4*$B$12)+(AF13*$AG$4*$B$13)+(AF14*$AG$4*$B$14)+(AF15*$AG$4*$B$15)+(AF16*$AG$4*$B$16)+(AF17*$AG$4*$B$17)+(AF18*$AG$4*$B$18)+(AF19*$AG$4*$B$19)+(AF20*$AG$4*$B$20)+(AF21*$AG$4*$B$21) | AH9: =AG9*$AH$4*1+AG9+(AG10*$AH$4*$B$10)+(AG11*$AH$4*$B$11)+(AG12*$AH$4*$B$12)+(AG13*$AH$4*$B$13)+(AG14*$AH$4*$B$14)+(AG15*$AH$4*$B$15)+(AG16*$AH$4*$B$16)+(AG17*$AH$4*$B$17)+(AG18*$AH$4*$B$18)+(AG19*$AH$4*$B$19)+(AG20*$AH$4*$B$20)+(AG21*$AH$4*$B$21) | AI9: =AH9*$AI$4*1+AH9+(AH10*$AI$4*$B$10)+(AH11*$AI$4*$B$11)+(AH12*$AI$4*$B$12)+(AH13*$AI$4*$B$13)+(AH14*$AI$4*$B$14)+(AH15*$AI$4*$B$15)+(AH16*$AI$4*$B$16)+(AH17*$AI$4*$B$17)+(AH18*$AI$4*$B$18)+(AH19*$AI$4*$B$19)+(AH20*$AI$4*$B$20)+(AH21*$AI$4*$B$21)+(AH20*$AI$4*(1-$B20-$C20)+AH20)-0.4408 | AJ9: =AI9*$AJ$4*1+AI9+(AI10*$AJ$4*$B$10)+(AI11*$AJ$4*$B$11)+(AI12*$AJ$4*$B$12)+(AI13*$AJ$4*$B$13)+(AI14*$AJ$4*$B$14)+(AI15*$AJ$4*$B$15)+(AI16*$AJ$4*$B$16)+(AI17*$AJ$4*$B$17)+(AI18*$AJ$4*$B$18)+(AI19*$AJ$4*$B$19)+(AI20*$AJ$4*$B$20)+(AI21*$AJ$4*$B$21)+(AI22*$AJ$4*$B$22) | AK9: =AJ9*$AK$4*1+AJ9+(AJ10*$AK$4*$B$10)+(AJ11*$AK$4*$B$11)+(AJ12*$AK$4*$B$12)+(AJ13*$AK$4*$B$13)+(AJ14*$AK$4*$B$14)+(AJ15*$AK$4*$B$15)+(AJ16*$AK$4*$B$16)+(AJ17*$AK$4*$B$17)+(AJ18*$AK$4*$B$18)+(AJ19*$AK$4*$B$19)+(AJ20*$AK$4*$B$20)+(AJ21*$AK$4*$B$21)+(AJ22*$AK$4*$B$22) | AL9: =AK9*$AL$4*1+AK9+(AK10*$AL$4*$B$10)+(AK11*$AL$4*$B$11)+(AK12*$AL$4*$B$12)+(AK13*$AL$4*$B$13)+(AK14*$AL$4*$B$14)+(AK15*$AL$4*$B$15)+(AK16*$AL$4*$B$16)+(AK17*$AL$4*$B$17)+(AK18*$AL$4*$B$18)+(AK19*$AL$4*$B$19)+(AK20*$AL$4*$B$20)+(AK21*$AL$4*$B$21)+(AK22*$AL$4*$B$22)+(AK23*$AL$4*$B$23) | AM9: =AL9*$AM$4*1+AL9+(AL10*$AM$4*$B$10)+(AL11*$AM$4*$B$11)+(AL12*$AM$4*$B$12)+(AL13*$AM$4*$B$13)+(AL14*$AM$4*$B$14)+(AL15*$AM$4*$B$15)+(AL16*$AM$4*$B$16)+(AL17*$AM$4*$B$17)+(AL18*$AM$4*$B$18)+(AL19*$AM$4*$B$19)+(AL20*$AM$4*$B$20)+(AL21*$AM$4*$B$21)+(AL22*$AM$4*$B$22)+(AL23*$AM$4*$B$23)+(AL24*$AM$4*$B$24)+(AL25*$AM$4*$B$25) | AN9: =AM9*$AN$4*1+AM9+(AM10*$AN$4*$B$10)+(AM11*$AN$4*$B$11)+(AM12*$AN$4*$B$12)+(AM13*$AN$4*$B$13)+(AM14*$AN$4*$B$14)+(AM15*$AN$4*$B$15)+(AM16*$AN$4*$B$16)+(AM17*$AN$4*$B$17)+(AM18*$AN$4*$B$18)+(AM19*$AN$4*$B$19)+(AM20*$AN$4*$B$20)+(AM21*$AN$4*$B$21)+(AM22*$AN$4*$B$22)+(AM23*$AN$4*$B$23)+(AM24*$AN$4*$B$24)+(AM25*$AN$4*$B$25) | AO9: =AN9*$AO$4*1+AN9+(AN10*$AO$4*$B$10)+(AN11*$AO$4*$B$11)+(AN12*$AO$4*$B$12)+(AN13*$AO$4*$B$13)+(AN14*$AO$4*$B$14)+(AN15*$AO$4*$B$15)+(AN16*$AO$4*$B$16)+(AN17*$AO$4*$B$17)+(AN18*$AO$4*$B$18)+(AN19*$AO$4*$B$19)+(AN20*$AO$4*$B$20)+(AN21*$AO$4*$B$21)+(AN22*$AO$4*$B$22)+(AN23*$AO$4*$B$23)+(AN24*$AO$4*$B$24)+(AN25*$AO$4*$B$25) | AP9: =AO9*$AP$4*1+AO9+(AO10*$AP$4*$B$10)+(AO11*$AP$4*$B$11)+(AO12*$AP$4*$B$12)+(AO13*$AP$4*$B$13)+(AO14*$AP$4*$B$14)+(AO15*$AP$4*$B$15)+(AO16*$AP$4*$B$16)+(AO17*$AP$4*$B$17)+(AO18*$AP$4*$B$18)+(AO19*$AP$4*$B$19)+(AO20*$AP$4*$B$20)+(AO21*$AP$4*$B$21)+(AO22*$AP$4*$B$22)+(AO23*$AP$4*$B$23)+(AO24*$AP$4*$B$24)+(AO25*$AP$4*$B$25) | AQ9: =AP9*$AQ$4*1+AP9+(AP10*$AQ$4*$B$10)+(AP11*$AQ$4*$B$11)+(AP12*$AQ$4*$B$12)+(AP13*$AQ$4*$B$13)+(AP14*$AQ$4*$B$14)+(AP15*$AQ$4*$B$15)+(AP16*$AQ$4*$B$16)+(AP17*$AQ$4*$B$17)+(AP18*$AQ$4*$B$18)+(AP19*$AQ$4*$B$19)+(AP20*$AQ$4*$B$20)+(AP21*$AQ$4*$B$21)+(AP22*$AQ$4*$B$22)+(AP23*$AQ$4*$B$23)+(AP24*$AQ$4*$B$24)+(AP25*$AQ$4*$B$25) | AR9: =AQ9*$AR$4*1+AQ9+(AQ10*$AR$4*$B$10)+(AQ11*$AR$4*$B$11)+(AQ12*$AR$4*$B$12)+(AQ13*$AR$4*$B$13)+(AQ14*$AR$4*$B$14)+(AQ15*$AR$4*$B$15)+(AQ16*$AR$4*$B$16)+(AQ17*$AR$4*$B$17)+(AQ18*$AR$4*$B$18)+(AQ19*$AR$4*$B$19)+(AQ20*$AR$4*$B$20)+(AQ21*$AR$4*$B$21)+(AQ22*$AR$4*$B$22)+(AQ23*$AR$4*$B$23)+(AQ24*$AR$4*$B$24)+(AQ25*$AR$4*$B$25)+(AQ12*$AR$4*(1-$B12)+AQ12-4.9895) | AS9: =AR9*$AS$4*1+AR9+(AR10*$AS$4*$B$10)+(AR11*$AS$4*$B$11)+(AR12*$AS$4*$B$12)+(AR13*$AS$4*$B$13)+(AR14*$AS$4*$B$14)+(AR15*$AS$4*$B$15)+(AR16*$AS$4*$B$16)+(AR17*$AS$4*$B$17)+(AR18*$AS$4*$B$18)+(AR19*$AS$4*$B$19)+(AR20*$AS$4*$B$20)+(AR21*$AS$4*$B$21)+(AR22*$AS$4*$B$22)+(AR23*$AS$4*$B$23)+(AR24*$AS$4*$B$24)+(AR25*$AS$4*$B$25) | AT9: =AS9*$AT$4*1+AS9+(AS10*$AT$4*$B$10)+(AS11*$AT$4*$B$11)+(AS12*$AT$4*$B$12)+(AS13*$AT$4*$B$13)+(AS14*$AT$4*$B$14)+(AS15*$AT$4*$B$15)+(AS16*$AT$4*$B$16)+(AS17*$AT$4*$B$17)+(AS18*$AT$4*$B$18)+(AS19*$AT$4*$B$19)+(AS20*$AT$4*$B$20)+(AS21*$AT$4*$B$21)+(AS22*$AT$4*$B$22)+(AS23*$AT$4*$B$23)+(AS24*$AT$4*$B$24)+(AS25*$AT$4*$B$25)+(AS22*$AT$4*(1-$B22-$C22)+AS22)-7.7852 | AU9: =AT9*$AU$4*1+AT9+(AT10*$AU$4*$B$10)+(AT11*$AU$4*$B$11)+(AT12*$AU$4*$B$12)+(AT13*$AU$4*$B$13)+(AT14*$AU$4*$B$14)+(AT15*$AU$4*$B$15)+(AT16*$AU$4*$B$16)+(AT17*$AU$4*$B$17)+(AT18*$AU$4*$B$18)+(AT19*$AU$4*$B$19)+(AT20*$AU$4*$B$20)+(AT21*$AU$4*$B$21)+(AT22*$AU$4*$B$22)+(AT23*$AU$4*$B$23)+(AT24*$AU$4*$B$24)+(AT25*$AU$4*$B$25)+(AT25*$AU$4*(1-$B25)+AT25)-3.4221 | AV9: =AU9*$AV$4*1+AU9+(AU10*$AV$4*$B$10)+(AU11*$AV$4*$B$11)+(AU12*$AV$4*$B$12)+(AU13*$AV$4*$B$13)+(AU14*$AV$4*$B$14)+(AU15*$AV$4*$B$15)+(AU16*$AV$4*$B$16)+(AU17*$AV$4*$B$17)+(AU18*$AV$4*$B$18)+(AU19*$AV$4*$B$19)+(AU20*$AV$4*$B$20)+(AU21*$AV$4*$B$21)+(AU22*$AV$4*$B$22)+(AU23*$AV$4*$B$23)+(AU24*$AV$4*$B$24)+(AU25*$AV$4*$B$25)+(AU26*$AV$4*$B$26) | AW9: =AV9*$AW$4*1+AV9+(AV10*$AW$4*$B$10)+(AV11*$AW$4*$B$11)+(AV12*$AW$4*$B$12)+(AV13*$AW$4*$B$13)+(AV14*$AW$4*$B$14)+(AV15*$AW$4*$B$15)+(AV16*$AW$4*$B$16)+(AV17*$AW$4*$B$17)+(AV18*$AW$4*$B$18)+(AV19*$AW$4*$B$19)+(AV20*$AW$4*$B$20)+(AV21*$AW$4*$B$21)+(AV22*$AW$4*$B$22)+(AV23*$AW$4*$B$23)+(AV24*$AW$4*$B$24)+(AV25*$AW$4*$B$25)+(AV26*$AW$4*$B$26) | AX9: =AW9*$AX$4*1+AW9+(AW10*$AX$4*$B$10)+(AW11*$AX$4*$B$11)+(AW12*$AX$4*$B$12)+(AW13*$AX$4*$B$13)+(AW14*$AX$4*$B$14)+(AW15*$AX$4*$B$15)+(AW16*$AX$4*$B$16)+(AW17*$AX$4*$B$17)+(AW18*$AX$4*$B$18)+(AW19*$AX$4*$B$19)+(AW20*$AX$4*$B$20)+(AW21*$AX$4*$B$21)+(AW22*$AX$4*$B$22)+(AW23*$AX$4*$B$23)+(AW24*$AX$4*$B$24)+(AW25*$AX$4*$B$25)+(AW26*$AX$4*$B$26)+AW11*$AX$4*(1-$B11)+AW11-3.99 | AY9: =AX9*$AY$4*1+AX9+(AX10*$AY$4*$B$10)+(AX11*$AY$4*$B$11)+(AX12*$AY$4*$B$12)+(AX13*$AY$4*$B$13)+(AX14*$AY$4*$B$14)+(AX15*$AY$4*$B$15)+(AX16*$AY$4*$B$16)+(AX17*$AY$4*$B$17)+(AX18*$AY$4*$B$18)+(AX19*$AY$4*$B$19)+(AX20*$AY$4*$B$20)+(AX21*$AY$4*$B$21)+(AX22*$AY$4*$B$22)+(AX23*$AY$4*$B$23)+(AX24*$AY$4*$B$24)+(AX25*$AY$4*$B$25)+(AX26*$AY$4*$B$26) | AZ9: =AY9*$AZ$4*1+AY9+(AY10*$AZ$4*$B$10)+(AY11*$AZ$4*$B$11)+(AY12*$AZ$4*$B$12)+(AY13*$AZ$4*$B$13)+(AY14*$AZ$4*$B$14)+(AY15*$AZ$4*$B$15)+(AY16*$AZ$4*$B$16)+(AY17*$AZ$4*$B$17)+(AY18*$AZ$4*$B$18)+(AY19*$AZ$4*$B$19)+(AY20*$AZ$4*$B$20)+(AY21*$AZ$4*$B$21)+(AY22*$AZ$4*$B$22)+(AY23*$AZ$4*$B$23)+(AY24*$AZ$4*$B$24)+(AY25*$AZ$4*$B$25)+(AY26*$AZ$4*$B$26) | BA9: =AZ9*$BA$4*1+AZ9+(AZ10*$BA$4*$B$10)+(AZ11*$BA$4*$B$11)+(AZ12*$BA$4*$B$12)+(AZ13*$BA$4*$B$13)+(AZ14*$BA$4*$B$14)+(AZ15*$BA$4*$B$15)+(AZ16*$BA$4*$B$16)+(AZ17*$BA$4*$B$17)+(AZ18*$BA$4*$B$18)+(AZ19*$BA$4*$B$19)+(AZ20*$BA$4*$B$20)+(AZ21*$BA$4*$B$21)+(AZ22*$BA$4*$B$22)+(AZ23*$BA$4*$B$23)+(AZ24*$BA$4*$B$24)+(AZ25*$BA$4*$B$25)+(AZ26*$BA$4*$B$26) | BB9: =BA9*BB$4*1+BA9+(BA10*BB$4*$B$10)+(BA11*BB$4*$B$11)+(BA12*BB$4*$B$12)+(BA13*BB$4*$B$13)+(BA14*BB$4*$B$14)+(BA15*BB$4*$B$15)+(BA16*BB$4*$B$16)+(BA17*BB$4*$B$17)+(BA18*BB$4*$B$18)+(BA19*BB$4*$B$19)+(BA20*BB$4*$B$20)+(BA21*BB$4*$B$21)+(BA22*BB$4*$B$22)+(BA23*BB$4*$B$23)+(BA24*BB$4*$B$24)+(BA25*BB$4*$B$25)+(BA26*BB$4*$B$26)+SUMIFS(Investments!$D:$D,Investments!$B:$B,$A9,Investments!$C:$C,"BTC",Investments!$A:$A,BB$8) | BC9: =BB9*BC$4*1+BB9+(BB10*BC$4*$B$10)+(BB11*BC$4*$B$11)+(BB12*BC$4*$B$12)+(BB13*BC$4*$B$13)+(BB14*BC$4*$B$14)+(BB15*BC$4*$B$15)+(BB16*BC$4*$B$16)+(BB17*BC$4*$B$17)+(BB18*BC$4*$B$18)+(BB19*BC$4*$B$19)+(BB20*BC$4*$B$20)+(BB21*BC$4*$B$21)+(BB22*BC$4*$B$22)+(BB23*BC$4*$B$23)+(BB24*BC$4*$B$24)+(BB25*BC$4*$B$25)+(BB26*BC$4*$B$26)+SUMIFS(Investments!$D:$D,Investments!$B:$B,$A9,Investments!$C:$C,"BTC",Investments!$A:$A,BC$8) | BD9: =BC9*BD$4*1+BC9+(BC10*BD$4*$B$10)+(BC11*BD$4*$B$11)+(BC12*BD$4*$B$12)+(BC13*BD$4*$B$13)+(BC14*BD$4*$B$14)+(BC15*BD$4*$B$15)+(BC16*BD$4*$B$16)+(BC17*BD$4*$B$17)+(BC18*BD$4*$B$18)+(BC19*BD$4*$B$19)+(BC20*BD$4*$B$20)+(BC21*BD$4*$B$21)+(BC22*BD$4*$B$22)+(BC23*BD$4*$B$23)+(BC24*BD$4*$B$24)+(BC25*BD$4*$B$25)+(BC26*BD$4*$B$26)+(BC27*BD$4*$B$27)+SUMIFS(Investments!$D:$D,Investments!$B:$B,$A9,Investments!$C:$C,"BTC",Investments!$A:$A,BD$8)+BC14*BD$4*(1-$B14)+BC14-4.3 | BE9: =BD9*BE$4*1+BD9+(BD10*BE$4*$B$10)+(BD11*BE$4*$B$11)+(BD12*BE$4*$B$12)+(BD13*BE$4*$B$13)+(BD14*BE$4*$B$14)+(BD15*BE$4*$B$15)+(BD16*BE$4*$B$16)+(BD17*BE$4*$B$17)+(BD18*BE$4*$B$18)+(BD19*BE$4*$B$19)+(BD20*BE$4*$B$20)+(BD21*BE$4*$B$21)+(BD22*BE$4*$B$22)+(BD23*BE$4*$B$23)+(BD24*BE$4*$B$24)+(BD25*BE$4*$B$25)+(BD26*BE$4*$B$26)+(BD27*BE$4*$B$27)+SUMIFS(Investments!$D:$D,Investments!$B:$B,$A9,Investments!$C:$C,"BTC",Investments!$A:$A,BE$8) | BF9: =BE9*BF$4*1+BE9+(BE10*BF$4*$B$10)+(BE11*BF$4*$B$11)+(BE12*BF$4*$B$12)+(BE13*BF$4*$B$13)+(BE14*BF$4*$B$14)+(BE15*BF$4*$B$15)+(BE16*BF$4*$B$16)+(BE17*BF$4*$B$17)+(BE18*BF$4*$B$18)+(BE19*BF$4*$B$19)+(BE20*BF$4*$B$20)+(BE21*BF$4*$B$21)+(BE22*BF$4*$B$22)+(BE23*BF$4*$B$23)+(BE24*BF$4*$B$24)+(BE25*BF$4*$B$25)+(BE26*BF$4*$B$26)+(BE27*BF$4*$B$27)+SUMIFS(Investments!$D:$D,Investments!$B:$B,$A9,Investments!$C:$C,"BTC",Investments!$A:$A,BF$8)
A10: Jose Molla | B10: 0.15 | D10: 3.468 | E10: =D10*E4*(1-$B10)+D10 | F10: =E10*F4*(1-$B10)+E10 | G10: =F10*$G$4*(1-$B10)+F10 | H10: =G10*$H$4*(1-$B10)+G10 | I10: =H10*$I$4*(1-$B10)+H10 | J10: =I10*$J$4*(1-$B10)+I10 | K10: =J10*$K$4*(1-$B10)+J10 | L10: =K10*$L$4*(1-$B10)+K10 | M10: =L10 | N10: =M10*$N$4*(1-$B10)+M10 | O10: =N10*$O$4*(1-$B10)+N10 | P10: =O10*$P$4*(1-$B10)+O10 | Q10: =P10*$Q$4*(1-$B10)+P10 | R10: =Q10*$R$4*(1-$B10)+Q10 | S10: =R10*$S$4*(1-$B10)+R10 | T10: =S10*$T$4*(1-$B10)+S10 | U10: =T10*$U$4*(1-$B10)+T10 | V10: =U10*$V$4*(1-$B10)+U10 | W10: =V10*$W$4*(1-$B10)+V10 | X10: =W10*$X$4*(1-$B10)+W10 | Y10: =X10*$Y$4*(1-$B10)+X10 | Z10: =Y10*$Z$4*(1-$B10)+Y10 | AA10: =Z10*$AA$4*(1-$B10)+Z10 | AB10: =AA10*$AB$4*(1-$B10)+AA10 | AC10: =AB10*$AC$4*(1-$B10)+AB10 | AD10: =AC10*$AD$4*(1-$B10)+AC10 | AE10: =AD10*$AE$4*(1-$B10)+AD10 | AF10: =AE10*$AF$4*(1-$B10)+AE10 | AG10: =AF10*$AG$4*(1-$B10)+AF10+0.062 | AH10: =AG10*$AH$4*(1-$B10)+AG10 | AI10: =AH10*$AI$4*(1-$B10)+AH10 | AJ10: =AI10*$AJ$4*(1-$B10)+AI10+0.4867 | AK10: =AJ10*$AK$4*(1-$B10)+AJ10 | AL10: =AK10*$AL$4*(1-$B10)+AK10+0.548 | AM10: =AL10*$AM$4*(1-$B10)+AL10 | AN10: =AM10*$AN$4*(1-$B10)+AM10 | AO10: =AN10*$AO$4*(1-$B10)+AN10 | AP10: =AO10*$AP$4*(1-$B10)+AO10 | AQ10: =AP10*$AQ$4*(1-$B10)+AP10 | AR10: =AQ10*$AR$4*(1-$B10)+AQ10 | AS10: =AR10*$AS$4*(1-$B10)+AR10 | AT10: =AS10*$AT$4*(1-$B10)+AS10 | AU10: =AT10*$AU$4*(1-$B10)+AT10 | AV10: =AU10*$AV$4*(1-$B10)+AU10 | AW10: =AV10*$AW$4*(1-$B10)+AV10 | AX10: =AW10*$AX$4*(1-$B10)+AW10 | AY10: =AX10*$AY$4*(1-$B10)+AX10 | AZ10: =AY10*$AZ$4*(1-$B10)+AY10 | BA10: =AZ10*$BA$4*(1-$B10)+AZ10 | BB10: =BA10*BB$4*(1-$B10)+BA10+SUMIFS(Investments!$D:$D,Investments!$B:$B,$A10,Investments!$C:$C,"BTC",Investments!$A:$A,BB$8) | BC10: =BB10*BC$4*(1-$B10)+BB10+SUMIFS(Investments!$D:$D,Investments!$B:$B,$A10,Investments!$C:$C,"BTC",Investments!$A:$A,BC$8) | BD10: =BC10*BD$4*(1-$B10)+BC10+SUMIFS(Investments!$D:$D,Investments!$B:$B,$A10,Investments!$C:$C,"BTC",Investments!$A:$A,BD$8) | BE10: =BD10*BE$4*(1-$B10)+BD10+SUMIFS(Investments!$D:$D,Investments!$B:$B,$A10,Investments!$C:$C,"BTC",Investments!$A:$A,BE$8) | BF10: =BE10*BF$4*(1-$B10)+BE10+SUMIFS(Investments!$D:$D,Investments!$B:$B,$A10,Investments!$C:$C,"BTC",Investments!$A:$A,BF$8)
A11: Kyle Gulamerian | B11: 0.15 | E11: 0 | F11: 2 | G11: =F11*$G$4*(1-$B11)+F11 | H11: =G11*$H$4*(1-$B11)+G11 | I11: =H11*$I$4*(1-$B11)+H11 | J11: =I11*$J$4*(1-$B11)+I11 | K11: =J11*$K$4*(1-$B11)+J11 | L11: =K11*$L$4*(1-$B11)+K11 | M11: =L11-L11 | N11: =M11*$N$4*(1-$B11)+M11 | O11: =N11*$O$4*(1-$B11)+N11 | P11: =O11*$P$4*(1-$B11)+O11 | Q11: =P11*$Q$4*(1-$B11)+P11 | R11: =Q11*$R$4*(1-$B11)+Q11+2.101 | S11: =R11*$S$4*(1-$B11)+R11 | T11: =S11*$T$4*(1-$B11)+S11-(S11*$T$4*(1-$B11)+S11) | U11: =T11*$U$4*(1-$B11)+T11 | V11: =U11*$V$4*(1-$B11)+U11-(U11*$V$4*(1-$B11)+U11) | W11: =V11*$W$4*(1-$B11)+V11-(V11*$W$4*(1-$B11)+V11) | X11: =W11*$X$4*(1-$B11)+W11-(W11*$X$4*(1-$B11)+W11) | Y11: =X11*$Y$4*(1-$B11)+X11-(X11*$Y$4*(1-$B11)+X11) | Z11: =Y11*$Z$4*(1-$B11)+Y11-(Y11*$Z$4*(1-$B11)+Y11) | AA11: =Z11*$AA$4*(1-$B11)+Z11-(Z11*$AA$4*(1-$B11)+Z11) | AB11: =AA11*$AB$4*(1-$B11)+AA11-(AA11*$AB$4*(1-$B11)+AA11) | AC11: =AB11*$AC$4*(1-$B11)+AB11-(AB11*$AC$4*(1-$B11)+AB11) | AD11: =AC11*$AD$4*(1-$B11)+AC11-(AC11*$AD$4*(1-$B11)+AC11) | AE11: =AD11*$AE$4*(1-$B11)+AD11-(AD11*$AE$4*(1-$B11)+AD11) | AF11: =AE11*$AF$4*(1-$B11)+AE11-(AE11*$AF$4*(1-$B11)+AE11) | AG11: =AF11*$AG$4*(1-$B11)+AF11-(AF11*$AG$4*(1-$B11)+AF11) | AH11: =AG11*$AH$4*(1-$B11)+AG11-(AG11*$AH$4*(1-$B11)+AG11) | AI11: =AH11*$AI$4*(1-$B11)+AH11-(AH11*$AI$4*(1-$B11)+AH11) | AJ11: =AI11*$AJ$4*(1-$B11)+AI11-(AI11*$AJ$4*(1-$B11)+AI11) | AK11: =AJ11*$AK$4*(1-$B11)+AJ11 | AL11: =AK11*$AL$4*(1-$B11)+AK11 | AM11: =AL11*$AM$4*(1-$B11)+AL11 | AN11: =AM11*$AN$4*(1-$B11)+AM11 | AO11: =AN11*$AO$4*(1-$B11)+AN11 | AP11: =AO11*$AP$4*(1-$B11)+AO11 | AQ11: =AP11*$AQ$4*(1-$B11)+AP11 | AR11: =AQ11*$AR$4*(1-$B11)+AQ11 | AS11: =AR11*$AS$4*(1-$B11)+AR11 | AT11: =AS11*$AT$4*(1-$B11)+AS11 | AU11: =AT11*$AU$4*(1-$B11)+AT11 | AV11: =AU11*$AV$4*(1-$B11)+AU11 | AW11: =AV11*$AW$4*(1-$B11)+AV11+3.9998 | AX11: =AW11*$AX$4*(1-$B11)+AW11-(AW11*$AX$4*(1-$B11)+AW11) | AY11: =AX11*$AY$4*(1-$B11)+AX11 | AZ11: =AY11*$AZ$4*(1-$B11)+AY11 | BA11: =AZ11*$BA$4*(1-$B11)+AZ11 | BB11: =BA11*BB$4*(1-$B11)+BA11+SUMIFS(Investments!$D:$D,Investments!$B:$B,$A11,Investments!$C:$C,"BTC",Investments!$A:$A,BB$8) | BC11: =BB11*BC$4*(1-$B11)+BB11+SUMIFS(Investments!$D:$D,Investments!$B:$B,$A11,Investments!$C:$C,"BTC",Investments!$A:$A,BC$8) | BD11: =BC11*BD$4*(1-$B11)+BC11+SUMIFS(Investments!$D:$D,Investments!$B:$B,$A11,Investments!$C:$C,"BTC",Investments!$A:$A,BD$8) | BE11: =BD11*BE$4*(1-$B11)+BD11+SUMIFS(Investments!$D:$D,Investments!$B:$B,$A11,Investments!$C:$C,"BTC",Investments!$A:$A,BE$8) | BF11: =BE11*BF$4*(1-$B11)+BE11+SUMIFS(Investments!$D:$D,Investments!$B:$B,$A11,Investments!$C:$C,"BTC",Investments!$A:$A,BF$8)
A12: Matthias Reiser | B12: 0.1 | E12: 0 | F12: 0 | G12: 0 | H12: 4.62 | I12: =H12*$I$4*(1-$B12)+H12 | J12: =I12*$J$4*(1-$B12)+I12 | K12: =J12*$K$4*(1-$B12)+J12 | L12: =K12*$L$4*(1-$B12)+K12 | M12: =L12-L12 | N12: =M12*$N$4*(1-$B12)+M12 | O12: =N12*$O$4*(1-$B12)+N12 | P12: =O12*$P$4*(1-$B12)+O12 | Q12: =P12*$Q$4*(1-$B12)+P12 | R12: =Q12*$R$4*(1-$B12)+Q12+4.8357 | S12: =R12*$S$4*(1-$B12)+R12 | T12: =S12*$T$4*(1-$B12)+S12 | U12: =T12*$U$4*(1-$B12)+T12 | V12: =U12*$V$4*(1-$B12)+U12 | W12: =V12*$W$4*(1-$B12)+V12 | X12: =W12*$X$4*(1-$B12)+W12 | Y12: =X12*$Y$4*(1-$B12)+X12 | Z12: =Y12*$Z$4*(1-$B12)+Y12 | AA12: =Z12*$AA$4*(1-$B12)+Z12 | AB12: =AA12*$AB$4*(1-$B12)+AA12 | AC12: =AB12*$AC$4*(1-$B12)+AB12 | AD12: =AC12*$AD$4*(1-$B12)+AC12 | AE12: =AD12*$AE$4*(1-$B12)+AD12 | AF12: =AE12*$AF$4*(1-$B12)+AE12 | AG12: =AF12*$AG$4*(1-$B12)+AF12 | AH12: =AG12*$AH$4*(1-$B12)+AG12 | AI12: =AH12*$AI$4*(1-$B12)+AH12 | AJ12: =AI12*$AJ$4*(1-$B12)+AI12 | AK12: =AJ12*$AK$4*(1-$B12)+AJ12 | AL12: =AK12*$AL$4*(1-$B12)+AK12 | AM12: =AL12*$AM$4*(1-$B12)+AL12 | AN12: =AM12*$AN$4*(1-$B12)+AM12 | AO12: =AN12*$AO$4*(1-$B12)+AN12 | AP12: =AO12*$AP$4*(1-$B12)+AO12 | AQ12: =AP12*$AQ$4*(1-$B12)+AP12 | AR12: =AQ12*$AR$4*(1-$B12)+AQ12-(AQ12*$AR$4*(1-$B12)+AQ12) | AS12: =AR12*$AS$4*(1-$B12)+AR12 | AT12: =AS12*$AT$4*(1-$B12)+AS12 | AU12: =AT12*$AU$4*(1-$B12)+AT12 | AV12: =AU12*$AV$4*(1-$B12)+AU12 | AW12: =AV12*$AW$4*(1-$B12)+AV12 | AX12: =AW12*$AX$4*(1-$B12)+AW12 | AY12: =AX12*$AY$4*(1-$B12)+AX12 | AZ12: =AY12*$AZ$4*(1-$B12)+AY12 | BA12: =AZ12*$BA$4*(1-$B12)+AZ12 | BB12: =BA12*BB$4*(1-$B12)+BA12+SUMIFS(Investments!$D:$D,Investments!$B:$B,$A12,Investments!$C:$C,"BTC",Investments!$A:$A,BB$8) | BC12: =BB12*BC$4*(1-$B12)+BB12+SUMIFS(Investments!$D:$D,Investments!$B:$B,$A12,Investments!$C:$C,"BTC",Investments!$A:$A,BC$8) | BD12: =BC12*BD$4*(1-$B12)+BC12+SUMIFS(Investments!$D:$D,Investments!$B:$B,$A12,Investments!$C:$C,"BTC",Investments!$A:$A,BD$8) | BE12: =BD12*BE$4*(1-$B12)+BD12+SUMIFS(Investments!$D:$D,Investments!$B:$B,$A12,Investments!$C:$C,"BTC",Investments!$A:$A,BE$8) | BF12: =BE12*BF$4*(1-$B12)+BE12+SUMIFS(Investments!$D:$D,Investments!$B:$B,$A12,Investments!$C:$C,"BTC",Investments!$A:$A,BF$8)
A13: Thomas Puech | B13: 0 | E13: 0 | F13: 0 | G13: 0 | H13: 6.5193 | I13: =H13*$I$4*(1-$B13)+H13 | J13: =I13*$J$4*(1-$B13)+I13 | K13: =J13*$K$4*(1-$B13)+J13 | L13: =K13*$L$4*(1-$B13)+K13 | M13: =L13 | N13: =M13*$N$4*(1-$B13)+M13 | O13: =N13*$O$4*(1-$B13)+N13 | P13: =O13*$P$4*(1-$B13)+O13 | Q13: =(P13*$Q$4*(1-$B13)+P13)-(P13*$Q$4*(1-$B13)+P13) | R13: =Q13*$R$4*(1-$B13)+Q13 | S13: =R13*$S$4*(1-$B13)+R13 | T13: =S13*$T$4*(1-$B13)+S13 | U13: =T13*$U$4*(1-$B13)+T13 | V13: =U13*$V$4*(1-$B13)+U13 | W13: =V13*$W$4*(1-$B13)+V13 | X13: =W13*$X$4*(1-$B13)+W13+6.69 | Y13: =X13*$Y$4*(1-$B13)+X13 | Z13: =Y13*$Z$4*(1-$B13)+Y13 | AA13: =Z13*$AA$4*(1-$B13)+Z13 | AB13: =AA13*$AB$4*(1-$B13)+AA13 | AC13: =AB13*$AC$4*(1-$B13)+AB13 | AD13: =AC13*$AD$4*(1-$B13)+AC13 | AE13: =AD13*$AE$4*(1-$B13)+AD13 | AF13: =AE13*$AF$4*(1-$B13)+AE13 | AG13: =AF13*$AG$4*(1-$B13)+AF13 | AH13: =AG13*$AH$4*(1-$B13)+AG13 | AI13: =AH13*$AI$4*(1-$B13)+AH13 | AJ13: =AI13*$AJ$4*(1-$B13)+AI13 | AK13: =AJ13*$AK$4*(1-$B13)+AJ13 | AL13: =AK13*$AL$4*(1-$B13)+AK13 | AM13: =AL13*$AM$4*(1-$B13)+AL13 | AN13: =AM13*$AN$4*(1-$B13)+AM13 | AO13: =AN13*$AO$4*(1-$B13)+AN13 | AP13: =AO13*$AP$4*(1-$B13)+AO13+0.657 | AQ13: =AP13*$AQ$4*(1-$B13)+AP13 | AR13: =AQ13*$AR$4*(1-$B13)+AQ13 | AS13: =AR13*$AS$4*(1-$B13)+AR13 | AT13: =AS13*$AT$4*(1-$B13)+AS13 | AU13: =AT13*$AU$4*(1-$B13)+AT13 | AV13: =AU13*$AV$4*(1-$B13)+AU13+0.1135766 | AW13: =AV13*$AW$4*(1-$B13)+AV13 | AX13: =AW13*$AX$4*(1-$B13)+AW13 | AY13: =AX13*$AY$4*(1-$B13)+AX13+0.14207 | AZ13: =AY13*$AZ$4*(1-$B13)+AY13 | BA13: =AZ13*$BA$4*(1-$B13)+AZ13+0.60672 | BB13: =BA13*BB$4*(1-$B13)+BA13+SUMIFS(Investments!$D:$D,Investments!$B:$B,$A13,Investments!$C:$C,"BTC",Investments!$A:$A,BB$8) | BC13: =BB13*BC$4*(1-$B13)+BB13+SUMIFS(Investments!$D:$D,Investments!$B:$B,$A13,Investments!$C:$C,"BTC",Investments!$A:$A,BC$8) | BD13: =BC13*BD$4*(1-$B13)+BC13+SUMIFS(Investments!$D:$D,Investments!$B:$B,$A13,Investments!$C:$C,"BTC",Investments!$A:$A,BD$8) | BE13: =BD13*BE$4*(1-$B13)+BD13+SUMIFS(Investments!$D:$D,Investments!$B:$B,$A13,Investments!$C:$C,"BTC",Investments!$A:$A,BE$8) | BF13: =BE13*BF$4*(1-$B13)+BE13+SUMIFS(Investments!$D:$D,Investments!$B:$B,$A13,Investments!$C:$C,"BTC",Investments!$A:$A,BF$8)
A14: Danielle Richetta | B14: 0.1 | E14: 0 | F14: 0 | G14: 0 | H14: 5.2 | I14: =H14*$I$4*(1-$B14)+H14 | J14: =I14*$J$4*(1-$B14)+I14-0.27 | K14: =J14*$K$4*(1-$B14)+J14 | L14: =K14*$L$4*(1-$B14)+K14-0.124 | M14: =L14-L14 | N14: =M14*$N$4*(1-$B14)+M14 | O14: =N14*$O$4*(1-$B14)+N14 | P14: =O14*$P$4*(1-$B14)+O14 | Q14: =P14*$Q$4*(1-$B14)+P14 | R14: =Q14*$R$4*(1-$B14)+Q14+5.0334 | S14: =R14*$S$4*(1-$B14)+R14 | T14: =S14*$T$4*(1-$B14)+S14 | U14: =T14*$U$4*(1-$B14)+T14-0.13 | V14: =U14*$V$4*(1-$B14)+U14 | W14: =V14*$W$4*(1-$B14)+V14 | X14: =W14*$X$4*(1-$B14)+W14 | Y14: =X14*$Y$4*(1-$B14)+X14 | Z14: =Y14*$Z$4*(1-$B14)+Y14-0.26 | AA14: =Z14*$AA$4*(1-$B14)+Z14 | AB14: =AA14*$AB$4*(1-$B14)+AA14-0.11 | AC14: =AB14*$AC$4*(1-$B14)+AB14 | AD14: =AC14*$AD$4*(1-$B14)+AC14 | AE14: =AD14*$AE$4*(1-$B14)+AD14 | AF14: =AE14*$AF$4*(1-$B14)+AE14 | AG14: =AF14*$AG$4*(1-$B14)+AF14 | AH14: =AG14*$AH$4*(1-$B14)+AG14 | AI14: =AH14*$AI$4*(1-$B14)+AH14-0.283 | AJ14: =AI14*$AJ$4*(1-$B14)+AI14 | AK14: =AJ14*$AK$4*(1-$B14)+AJ14 | AL14: =AK14*$AL$4*(1-$B14)+AK14 | AM14: =AL14*$AM$4*(1-$B14)+AL14 | AN14: =AM14*$AN$4*(1-$B14)+AM14 | AO14: =AN14*$AO$4*(1-$B14)+AN14 | AP14: =AO14*$AP$4*(1-$B14)+AO14 | AQ14: =AP14*$AQ$4*(1-$B14)+AP14 | AR14: =AQ14*$AR$4*(1-$B14)+AQ14 | AS14: =AR14*$AS$4*(1-$B14)+AR14 | AT14: =AS14*$AT$4*(1-$B14)+AS14 | AU14: =AT14*$AU$4*(1-$B14)+AT14 | AV14: =AU14*$AV$4*(1-$B14)+AU14 | AW14: =AV14*$AW$4*(1-$B14)+AV14-0.12 | AX14: =AW14*$AX$4*(1-$B14)+AW14 | AY14: =AX14*$AY$4*(1-$B14)+AX14 | AZ14: =AY14*$AZ$4*(1-$B14)+AY14 | BA14: =AZ14*$BA$4*(1-$B14)+AZ14 | BB14: =BA14*BB$4*(1-$B14)+BA14+SUMIFS(Investments!$D:$D,Investments!$B:$B,$A14,Investments!$C:$C,"BTC",Investments!$A:$A,BB$8) | BC14: =BB14*BC$4*(1-$B14)+BB14+SUMIFS(Investments!$D:$D,Investments!$B:$B,$A14,Investments!$C:$C,"BTC",Investments!$A:$A,BC$8) | BD14: =BC14*BD$4*(1-$B14)+BC14-(BC14*BD$4*(1-$B14)+BC14) | BE14: =BD14*BE$4*(1-$B14)+BD14-(BD14*BE$4*(1-$B14)+BD14) | BF14: =BE14*BF$4*(1-$B14)+BE14-(BE14*BF$4*(1-$B14)+BE14)
A15: Kabbaj | B15: 0.2 | E15: 0 | F15: 0 | G15: 0 | H15: 0 | I15: 0 | J15: 0 | K15: 0 | L15: 0 | M15: 0 | N15: 0 | O15: 0 | P15: 0 | Q15: 0 | R15: 0 | S15: 0 | T15: 0 | U15: 0 | V15: 2 | W15: =V15*$W$4*(1-$B15)+V15 | X15: =W15*$X$4*(1-$B15)+W15+0.9914 | Y15: =X15*$Y$4*(1-$B15)+X15 | Z15: =Y15*$Z$4*(1-$B15)+Y15 | AA15: =Z15*$AA$4*(1-$B15)+Z15+0.6 | AB15: =AA15*$AB$4*(1-$B15)+AA15 | AC15: =AB15*$AC$4*(1-$B15)+AB15+0.9102 | AD15: =AC15*$AD$4*(1-$B15)+AC15 | AE15: =AD15*$AE$4*(1-$B15)+AD15 | AF15: =AE15*$AF$4*(1-$B15)+AE15 | AG15: =AF15*$AG$4*(1-$B15)+AF15 | AH15: =AG15*$AH$4*(1-$B15)+AG15 | AI15: =AH15*$AI$4*(1-$B15)+AH15 | AJ15: =AI15*$AJ$4*(1-$B15)+AI15 | AK15: =AJ15*$AK$4*(1-$B15)+AJ15 | AL15: =AK15*$AL$4*(1-$B15)+AK15 | AM15: =AL15*$AM$4*(1-$B15)+AL15 | AN15: =AM15*$AN$4*(1-$B15)+AM15 | AO15: =AN15*$AO$4*(1-$B15)+AN15 | AP15: =AO15*$AP$4*(1-$B15)+AO15 | AQ15: =AP15*$AQ$4*(1-$B15)+AP15 | AR15: =AQ15*$AR$4*(1-$B15)+AQ15 | AS15: =AR15*$AS$4*(1-$B15)+AR15 | AT15: =AS15*$AT$4*(1-$B15)+AS15 | AU15: =AT15*$AU$4*(1-$B15)+AT15+2.1577 | AV15: =AU15*$AV$4*(1-$B15)+AU15 | AW15: =AV15*$AW$4*(1-$B15)+AV15 | AX15: =AW15*$AX$4*(1-$B15)+AW15 | AY15: =AX15*$AY$4*(1-$B15)+AX15 | AZ15: =AY15*$AZ$4*(1-$B15)+AY15 | BA15: =AZ15*$BA$4*(1-$B15)+AZ15 | BB15: =BA15*BB$4*(1-$B15)+BA15+SUMIFS(Investments!$D:$D,Investments!$B:$B,$A15,Investments!$C:$C,"BTC",Investments!$A:$A,BB$8) | BC15: =BB15*BC$4*(1-$B15)+BB15+SUMIFS(Investments!$D:$D,Investments!$B:$B,$A15,Investments!$C:$C,"BTC",Investments!$A:$A,BC$8) | BD15: =BC15*BD$4*(1-$B15)+BC15+SUMIFS(Investments!$D:$D,Investments!$B:$B,$A15,Investments!$C:$C,"BTC",Investments!$A:$A,BD$8) | BE15: =BD15*BE$4*(1-$B15)+BD15+SUMIFS(Investments!$D:$D,Investments!$B:$B,$A15,Investments!$C:$C,"BTC",Investments!$A:$A,BE$8) | BF15: =BE15*BF$4*(1-$B15)+BE15+SUMIFS(Investments!$D:$D,Investments!$B:$B,$A15,Investments!$C:$C,"BTC",Investments!$A:$A,BF$8)
A16: Victoria Pariente-Cohen | B16: 0 | E16: 0 | F16: 0 | G16: 0 | H16: 0 | I16: 0 | J16: 0 | K16: 0 | L16: 0 | M16: 0 | N16: 0 | O16: 0 | P16: 0 | Q16: 0 | R16: 0 | S16: 0 | T16: 0 | U16: 0 | V16: 0 | W16: 0 | X16: =W16*$X$4*(1-$B16)+W16+0.1484 | Y16: =X16*$Y$4*(1-$B16)+X16 | Z16: =Y16*$Z$4*(1-$B16)+Y16 | AA16: =Z16*$AA$4*(1-$B16)+Z16 | AB16: =AA16*$AB$4*(1-$B16)+AA16 | AC16: =AB16*$AC$4*(1-$B16)+AB16 | AD16: =AC16*$AD$4*(1-$B16)+AC16 | AE16: =AD16*$AE$4*(1-$B16)+AD16 | AF16: =AE16*$AF$4*(1-$B16)+AE16 | AG16: =AF16*$AG$4*(1-$B16)+AF16 | AH16: =AG16*$AH$4*(1-$B16)+AG16 | AI16: =AH16*$AI$4*(1-$B16)+AH16 | AJ16: =AI16*$AJ$4*(1-$B16)+AI16 | AK16: =AJ16*$AK$4*(1-$B16)+AJ16 | AL16: =AK16*$AL$4*(1-$B16)+AK16 | AM16: =AL16*$AM$4*(1-$B16)+AL16 | AN16: =AM16*$AN$4*(1-$B16)+AM16 | AO16: =AN16*$AO$4*(1-$B16)+AN16 | AP16: =AO16*$AP$4*(1-$B16)+AO16 | AQ16: =AP16*$AQ$4*(1-$B16)+AP16 | AR16: =AQ16*$AR$4*(1-$B16)+AQ16 | AS16: =AR16*$AS$4*(1-$B16)+AR16 | AT16: =AS16*$AT$4*(1-$B16)+AS16 | AU16: =AT16*$AU$4*(1-$B16)+AT16 | AV16: =AU16*$AV$4*(1-$B16)+AU16 | AW16: =AV16*$AW$4*(1-$B16)+AV16 | AX16: =AW16*$AX$4*(1-$B16)+AW16 | AY16: =AX16*$AY$4*(1-$B16)+AX16 | AZ16: =AY16*$AZ$4*(1-$B16)+AY16 | BA16: =AZ16*$BA$4*(1-$B16)+AZ16 | BB16: =BA16*BB$4*(1-$B16)+BA16+SUMIFS(Investments!$D:$D,Investments!$B:$B,$A16,Investments!$C:$C,"BTC",Investments!$A:$A,BB$8) | BC16: =BB16*BC$4*(1-$B16)+BB16+SUMIFS(Investments!$D:$D,Investments!$B:$B,$A16,Investments!$C:$C,"BTC",Investments!$A:$A,BC$8) | BD16: =BC16*BD$4*(1-$B16)+BC16+SUMIFS(Investments!$D:$D,Investments!$B:$B,$A16,Investments!$C:$C,"BTC",Investments!$A:$A,BD$8) | BE16: =BD16*BE$4*(1-$B16)+BD16+SUMIFS(Investments!$D:$D,Investments!$B:$B,$A16,Investments!$C:$C,"BTC",Investments!$A:$A,BE$8) | BF16: =BE16*BF$4*(1-$B16)+BE16+SUMIFS(Investments!$D:$D,Investments!$B:$B,$A16,Investments!$C:$C,"BTC",Investments!$A:$A,BF$8)
A17: Nathanaël Cohen | B17: 0 | E17: 0 | F17: 0 | G17: 0 | H17: 0 | I17: 0 | J17: 0 | K17: 0 | L17: 0 | M17: 0 | N17: 0 | O17: 0 | P17: 0 | Q17: 0 | R17: 0 | S17: 0 | T17: 0 | U17: 0 | V17: 0 | W17: 0 | X17: =W17*$X$4*(1-$B17)+W17+0.446 | Y17: =X17*$Y$4*(1-$B17)+X17 | Z17: =Y17*$Z$4*(1-$B17)+Y17 | AA17: =Z17*$AA$4*(1-$B17)+Z17 | AB17: =AA17*$AB$4*(1-$B17)+AA17 | AC17: =AB17*$AC$4*(1-$B17)+AB17 | AD17: =AC17*$AD$4*(1-$B17)+AC17 | AE17: =AD17*$AE$4*(1-$B17)+AD17 | AF17: =AE17*$AF$4*(1-$B17)+AE17 | AG17: =AF17*$AG$4*(1-$B17)+AF17 | AH17: =AG17*$AH$4*(1-$B17)+AG17 | AI17: =AH17*$AI$4*(1-$B17)+AH17 | AJ17: =AI17*$AJ$4*(1-$B17)+AI17 | AK17: =AJ17*$AK$4*(1-$B17)+AJ17 | AL17: =AK17*$AL$4*(1-$B17)+AK17 | AM17: =AL17*$AM$4*(1-$B17)+AL17 | AN17: =AM17*$AN$4*(1-$B17)+AM17 | AO17: =AN17*$AO$4*(1-$B17)+AN17 | AP17: =AO17*$AP$4*(1-$B17)+AO17 | AQ17: =AP17*$AQ$4*(1-$B17)+AP17 | AR17: =AQ17*$AR$4*(1-$B17)+AQ17 | AS17: =AR17*$AS$4*(1-$B17)+AR17 | AT17: =AS17*$AT$4*(1-$B17)+AS17 | AU17: =AT17*$AU$4*(1-$B17)+AT17 | AV17: =AU17*$AV$4*(1-$B17)+AU17 | AW17: =AV17*$AW$4*(1-$B17)+AV17 | AX17: =AW17*$AX$4*(1-$B17)+AW17 | AY17: =AX17*$AY$4*(1-$B17)+AX17 | AZ17: =AY17*$AZ$4*(1-$B17)+AY17 | BA17: =AZ17*$BA$4*(1-$B17)+AZ17 | BB17: =BA17*BB$4*(1-$B17)+BA17+SUMIFS(Investments!$D:$D,Investments!$B:$B,$A17,Investments!$C:$C,"BTC",Investments!$A:$A,BB$8) | BC17: =BB17*BC$4*(1-$B17)+BB17+SUMIFS(Investments!$D:$D,Investments!$B:$B,$A17,Investments!$C:$C,"BTC",Investments!$A:$A,BC$8) | BD17: =BC17*BD$4*(1-$B17)+BC17+SUMIFS(Investments!$D:$D,Investments!$B:$B,$A17,Investments!$C:$C,"BTC",Investments!$A:$A,BD$8) | BE17: =BD17*BE$4*(1-$B17)+BD17+SUMIFS(Investments!$D:$D,Investments!$B:$B,$A17,Investments!$C:$C,"BTC",Investments!$A:$A,BE$8) | BF17: =BE17*BF$4*(1-$B17)+BE17+SUMIFS(Investments!$D:$D,Investments!$B:$B,$A17,Investments!$C:$C,"BTC",Investments!$A:$A,BF$8)
A18: Blondish | B18: 0 | E18: 0 | F18: 0 | G18: 0 | H18: 0 | I18: 0 | J18: 0 | K18: 0 | L18: 0 | M18: 0 | N18: 0 | O18: 0 | P18: 0 | Q18: 0 | R18: 0 | S18: 0 | T18: 0 | U18: 0 | V18: 0 | W18: 0 | X18: =W18*$X$4*(1-$B18)+W18+4.0996 | Y18: =X18*$Y$4*(1-$B18)+X18 | Z18: =Y18*$Z$4*(1-$B18)+Y18 | AA18: =Z18*$AA$4*(1-$B18)+Z18 | AB18: =AA18*$AB$4*(1-$B18)+AA18 | AC18: =AB18*$AC$4*(1-$B18)+AB18 | AD18: =AC18*$AD$4*(1-$B18)+AC18 | AE18: =AD18*$AE$4*(1-$B18)+AD18 | AF18: =AE18*$AF$4*(1-$B18)+AE18 | AG18: =AF18*$AG$4*(1-$B18)+AF18 | AH18: =AG18*$AH$4*(1-$B18)+AG18 | AI18: =AH18*$AI$4*(1-$B18)+AH18 | AJ18: =AI18*$AJ$4*(1-$B18)+AI18 | AK18: =AJ18*$AK$4*(1-$B18)+AJ18 | AL18: =AK18*$AL$4*(1-$B18)+AK18 | AM18: =AL18*$AM$4*(1-$B18)+AL18 | AN18: =AM18*$AN$4*(1-$B18)+AM18 | AO18: =AN18*$AO$4*(1-$B18)+AN18 | AP18: =AO18*$AP$4*(1-$B18)+AO18 | AQ18: =AP18*$AQ$4*(1-$B18)+AP18 | AR18: =AQ18*$AR$4*(1-$B18)+AQ18 | AS18: =AR18*$AS$4*(1-$B18)+AR18 | AT18: =AS18*$AT$4*(1-$B18)+AS18 | AU18: =AT18*$AU$4*(1-$B18)+AT18 | AV18: =AU18*$AV$4*(1-$B18)+AU18 | AW18: =AV18*$AW$4*(1-$B18)+AV18 | AX18: =AW18*$AX$4*(1-$B18)+AW18 | AY18: =AX18*$AY$4*(1-$B18)+AX18 | AZ18: =AY18*$AZ$4*(1-$B18)+AY18 | BA18: =AZ18*$BA$4*(1-$B18)+AZ18 | BB18: =BA18*BB$4*(1-$B18)+BA18+SUMIFS(Investments!$D:$D,Investments!$B:$B,$A18,Investments!$C:$C,"BTC",Investments!$A:$A,BB$8) | BC18: =BB18*BC$4*(1-$B18)+BB18+SUMIFS(Investments!$D:$D,Investments!$B:$B,$A18,Investments!$C:$C,"BTC",Investments!$A:$A,BC$8) | BD18: =BC18*BD$4*(1-$B18)+BC18+SUMIFS(Investments!$D:$D,Investments!$B:$B,$A18,Investments!$C:$C,"BTC",Investments!$A:$A,BD$8) | BE18: =BD18*BE$4*(1-$B18)+BD18+SUMIFS(Investments!$D:$D,Investments!$B:$B,$A18,Investments!$C:$C,"BTC",Investments!$A:$A,BE$8) | BF18: =BE18*BF$4*(1-$B18)+BE18+SUMIFS(Investments!$D:$D,Investments!$B:$B,$A18,Investments!$C:$C,"BTC",Investments!$A:$A,BF$8)
A19: Oliver Loisel | B19: 0.1 | E19: 0 | F19: 0 | G19: 0 | H19: 0 | I19: 0 | J19: 0 | K19: 0 | L19: 0 | M19: 0 | N19: 0 | O19: 0 | P19: 0 | Q19: 0 | R19: 0 | S19: 0 | T19: 0 | U19: 0 | V19: 0 | W19: 0 | X19: 0 | Y19: =X19*$Y$4*(1-$B19)+X19+2.115364 | Z19: =Y19*$Z$4*(1-$B19)+Y19 | AA19: =Z19*$AA$4*(1-$B19)+Z19 | AB19: =AA19*$AB$4*(1-$B19)+AA19 | AC19: =AB19*$AC$4*(1-$B19)+AB19 | AD19: =AC19*$AD$4*(1-$B19)+AC19 | AE19: =AD19*$AE$4*(1-$B19)+AD19 | AF19: =AE19*$AF$4*(1-$B19)+AE19 | AG19: =AF19*$AG$4*(1-$B19)+AF19 | AH19: =AG19*$AH$4*(1-$B19)+AG19 | AI19: =AH19*$AI$4*(1-$B19)+AH19 | AJ19: =AI19*$AJ$4*(1-$B19)+AI19 | AK19: =AJ19*$AK$4*(1-$B19)+AJ19 | AL19: =AK19*$AL$4*(1-$B19)+AK19 | AM19: =AL19*$AM$4*(1-$B19)+AL19 | AN19: =AM19*$AN$4*(1-$B19)+AM19 | AO19: =AN19*$AO$4*(1-$B19)+AN19 | AP19: =AO19*$AP$4*(1-$B19)+AO19 | AQ19: =AP19*$AQ$4*(1-$B19)+AP19 | AR19: =AQ19*$AR$4*(1-$B19)+AQ19 | AS19: =AR19*$AS$4*(1-$B19)+AR19 | AT19: =AS19*$AT$4*(1-$B19)+AS19 | AU19: =AT19*$AU$4*(1-$B19)+AT19 | AV19: =AU19*$AV$4*(1-$B19)+AU19 | AW19: =AV19*$AW$4*(1-$B19)+AV19 | AX19: =AW19*$AX$4*(1-$B19)+AW19 | AY19: =AX19*$AY$4*(1-$B19)+AX19 | AZ19: =AY19*$AZ$4*(1-$B19)+AY19 | BA19: =AZ19*$BA$4*(1-$B19)+AZ19 | BB19: =BA19*BB$4*(1-$B19)+BA19+SUMIFS(Investments!$D:$D,Investments!$B:$B,$A19,Investments!$C:$C,"BTC",Investments!$A:$A,BB$8) | BC19: =BB19*BC$4*(1-$B19)+BB19+SUMIFS(Investments!$D:$D,Investments!$B:$B,$A19,Investments!$C:$C,"BTC",Investments!$A:$A,BC$8) | BD19: =BC19*BD$4*(1-$B19)+BC19+SUMIFS(Investments!$D:$D,Investments!$B:$B,$A19,Investments!$C:$C,"BTC",Investments!$A:$A,BD$8) | BE19: =BD19*BE$4*(1-$B19)+BD19+SUMIFS(Investments!$D:$D,Investments!$B:$B,$A19,Investments!$C:$C,"BTC",Investments!$A:$A,BE$8) | BF19: =BE19*BF$4*(1-$B19)+BE19+SUMIFS(Investments!$D:$D,Investments!$B:$B,$A19,Investments!$C:$C,"BTC",Investments!$A:$A,BF$8)
A20: Paul Johnson | B20: 0.135 | C20: 0.015 | E20: 0 | F20: 0 | G20: 0 | H20: 0 | I20: 0 | J20: 0 | K20: 0 | L20: 0 | M20: 0 | N20: 0 | O20: 0 | P20: 0 | Q20: 0 | R20: 0 | S20: 0 | T20: 0 | U20: 0 | V20: 0 | W20: 0 | X20: 0 | Y20: 0 | Z20: 0 | AA20: 0 | AB20: 0 | AC20: 0 | AD20: 0 | AE20: 0 | AF20: =AE20*$AF$4*(1-$B20-$C20)+AE20+0.4395 | AG20: =AF20*$AG$4*(1-$B20-$C20)+AF20 | AH20: =AG20*$AH$4*(1-$B20-$C20)+AG20 | AI20: =AH20*$AI$4*(1-$B20-$C20)+AH20-(AH20*$AI$4*(1-$B20-$C20)+AH20) | AJ20: =AI20*$AJ$4*(1-$B20-$C20)+AI20-(AI20*$AJ$4*(1-$B20-$C20)+AI20) | AK20: =AJ20*$AK$4*(1-$B20-$C20)+AJ20 | AL20: =AK20*$AL$4*(1-$B20-$C20)+AK20 | AM20: =AL20*$AM$4*(1-$B20-$C20)+AL20 | AN20: =AM20*$AN$4*(1-$B20-$C20)+AM20 | AO20: =AN20*$AO$4*(1-$B20-$C20)+AN20 | AP20: =AO20*$AP$4*(1-$B20-$C20)+AO20 | AQ20: =AP20*$AQ$4*(1-$B20-$C20)+AP20 | AR20: =AQ20*$AR$4*(1-$B20-$C20)+AQ20 | AS20: =AR20*$AS$4*(1-$B20-$C20)+AR20 | AT20: =AS20*$AT$4*(1-$B20-$C20)+AS20 | AU20: =AT20*$AU$4*(1-$B20-$C20)+AT20 | AV20: =AU20*$AV$4*(1-$B20-$C20)+AU20 | AW20: =AV20*$AW$4*(1-$B20-$C20)+AV20 | AX20: =AW20*$AX$4*(1-$B20-$C20)+AW20 | AY20: =AX20*$AY$4*(1-$B20-$C20)+AX20 | AZ20: =AY20*$AZ$4*(1-$B20-$C20)+AY20 | BA20: =AZ20*$BA$4*(1-$B20-$C20)+AZ20 | BB20: =BA20*BB$4*(1-$B20-$C20)+BA20+SUMIFS(Investments!$D:$D,Investments!$B:$B,$A20,Investments!$C:$C,"BTC",Investments!$A:$A,BB$8) | BC20: =BB20*BC$4*(1-$B20-$C20)+BB20+SUMIFS(Investments!$D:$D,Investments!$B:$B,$A20,Investments!$C:$C,"BTC",Investments!$A:$A,BC$8) | BD20: =BC20*BD$4*(1-$B20-$C20)+BC20+SUMIFS(Investments!$D:$D,Investments!$B:$B,$A20,Investments!$C:$C,"BTC",Investments!$A:$A,BD$8) | BE20: =BD20*BE$4*(1-$B20-$C20)+BD20+SUMIFS(Investments!$D:$D,Investments!$B:$B,$A20,Investments!$C:$C,"BTC",Investments!$A:$A,BE$8) | BF20: =BE20*BF$4*(1-$B20-$C20)+BE20+SUMIFS(Investments!$D:$D,Investments!$B:$B,$A20,Investments!$C:$C,"BTC",Investments!$A:$A,BF$8)
A21: Alex Jacobs | B21: 0.2 | E21: 0 | F21: 0 | G21: 0 | H21: 0 | I21: 0 | J21: 0 | K21: 0 | L21: 0 | M21: 0 | N21: 0 | O21: 0 | P21: 0 | Q21: 0 | R21: 0 | S21: 0 | T21: 0 | U21: 0 | V21: 0 | W21: 0 | X21: 0 | Y21: 0 | Z21: 0 | AA21: 0 | AB21: 0 | AC21: 0 | AD21: 0 | AE21: 0 | AF21: =AE21*$AF$4*(1-$B21)+AE21+(AE20*$AF$4*$C20) | AG21: =AF21*$AG$4*(1-$B21)+AF21+(AF20*$AG$4*$C20) | AH21: =AG21*$AH$4*(1-$B21)+AG21+(AG20*$AH$4*$C20) | AI21: =AH21*$AI$4*(1-$B21)+AH21+(AH20*$AI$4*$C20) | AJ21: =AI21*$AJ$4*(1-$B21)+AI21+(AI20*$AJ$4*$C20) | AK21: =AJ21*$AK$4*(1-$B21)+AJ21+(AJ20*$AK$4*$C20) | AL21: =AK21*$AL$4*(1-$B21)+AK21+(AK20*$AL$4*$C20) | AM21: =AL21*$AM$4*(1-$B21)+AL21+(AL20*$AM$4*$C20) | AN21: =AM21*$AN$4*(1-$B21)+AM21+(AM20*$AN$4*$C20) | AO21: =AN21*$AO$4*(1-$B21)+AN21+(AN20*$AO$4*$C20) | AP21: =AO21*$AP$4*(1-$B21)+AO21+(AO20*$AP$4*$C20) | AQ21: =AP21*$AQ$4*(1-$B21)+AP21+(AP20*$AQ$4*$C20) | AR21: =AQ21*$AR$4*(1-$B21)+AQ21+(AQ20*$AR$4*$C20) | AS21: =AR21*$AS$4*(1-$B21)+AR21+(AR20*$AS$4*$C20) | AT21: =AS21*$AT$4*(1-$B21)+AS21+(AS20*$AT$4*$C20) | AU21: =AT21*$AU$4*(1-$B21)+AT21+(AT20*$AU$4*$C20) | AV21: =AU21*$AV$4*(1-$B21)+AU21+(AU20*$AV$4*$C20) | AW21: =AV21*$AW$4*(1-$B21)+AV21+(AV20*$AW$4*$C20) | AX21: =AW21*$AX$4*(1-$B21)+AW21+(AW20*$AX$4*$C20) | AY21: =AX21*$AY$4*(1-$B21)+AX21+(AX20*$AY$4*$C20) | AZ21: =AY21*$AZ$4*(1-$B21)+AY21+(AY20*$AZ$4*$C20) | BA21: =AZ21*$BA$4*(1-$B21)+AZ21+(AZ20*$BA$4*$C20) | BB21: =BA21*BB$4*(1-$B21)+BA21+(BA20*BB$4*$C20)+SUMIFS(Investments!$D:$D,Investments!$B:$B,$A21,Investments!$C:$C,"BTC",Investments!$A:$A,BB$8) | BC21: =BB21*BC$4*(1-$B21)+BB21+(BB20*BC$4*$C20)+SUMIFS(Investments!$D:$D,Investments!$B:$B,$A21,Investments!$C:$C,"BTC",Investments!$A:$A,BC$8) | BD21: =BC21*BD$4*(1-$B21)+BC21+(BC20*BD$4*$C20)+SUMIFS(Investments!$D:$D,Investments!$B:$B,$A21,Investments!$C:$C,"BTC",Investments!$A:$A,BD$8) | BE21: =BD21*BE$4*(1-$B21)+BD21+(BD20*BE$4*$C20)+SUMIFS(Investments!$D:$D,Investments!$B:$B,$A21,Investments!$C:$C,"BTC",Investments!$A:$A,BE$8) | BF21: =BE21*BF$4*(1-$B21)+BE21+(BE20*BF$4*$C20)+SUMIFS(Investments!$D:$D,Investments!$B:$B,$A21,Investments!$C:$C,"BTC",Investments!$A:$A,BF$8)
A22: Sam Johnson | B22: 0.16 | C22: 0.04 | E22: 0 | F22: 0 | G22: 0 | H22: 0 | I22: =H22*$I$4*(1-$B22)+H22 | J22: =I22*$J$4*(1-$B22)+I22 | K22: =J22*$K$4*(1-$B22)+J22 | L22: =K22*$L$4*(1-$B22)+K22 | M22: =L22 | N22: =M22*$N$4*(1-$B22)+M22 | O22: =N22*$O$4*(1-$B22)+N22 | P22: =O22*$P$4*(1-$B22)+O22 | Q22: =(P22*$Q$4*(1-$B22)+P22)-(P22*$Q$4*(1-$B22)+P22) | R22: =Q22*$R$4*(1-$B22)+Q22 | S22: =R22*$S$4*(1-$B22)+R22 | T22: =S22*$T$4*(1-$B22)+S22 | U22: =T22*$U$4*(1-$B22)+T22 | V22: =U22*$V$4*(1-$B22)+U22 | W22: =V22*$W$4*(1-$B22)+V22 | X22: =W22*$X$4*(1-$B22)+W22 | Y22: =X22*$Y$4*(1-$B22)+X22 | Z22: =Y22*$Z$4*(1-$B22)+Y22 | AA22: =Z22*$AA$4*(1-$B22)+Z22 | AB22: =AA22*$AB$4*(1-$B22)+AA22 | AC22: =AB22*$AC$4*(1-$B22)+AB22 | AD22: =AC22*$AD$4*(1-$B22)+AC22 | AE22: =AD22*$AE$4*(1-$B22)+AD22 | AF22: =AE22*$AF$4*(1-$B22)+AE22 | AG22: =AF22*$AG$4*(1-$B22)+AF22 | AH22: =AG22*$AH$4*(1-$B22)+AG22 | AI22: =AH22*$AI$4*(1-$B22)+AH22 | AJ22: =AI22*$AJ$4*(1-$B22)+AI22 | AK22: =AJ22*$AK$4*(1-$B22-$C22)+AJ22+3.3 | AL22: =AK22*$AL$4*(1-$B22-$C22)+AK22+1 | AM22: =AL22*$AM$4*(1-$B22-$C22)+AL22 | AN22: =AM22*$AN$4*(1-$B22-$C22)+AM22+1.2 | AO22: =AN22*$AO$4*(1-$B22-$C22)+AN22+1.1 | AP22: =AO22*$AP$4*(1-$B22-$C22)+AO22 | AQ22: =AP22*$AQ$4*(1-$B22-$C22)+AP22+1.17 | AR22: =AQ22*$AR$4*(1-$B22-$C22)+AQ22 | AS22: =AR22*$AS$4*(1-$B22-$C22)+AR22 | AT22: =AS22*$AT$4*(1-$B22-$C22)+AS22-(AS22*$AT$4*(1-$B22-$C22)+AS22) | AU22: =AT22*$AU$4*(1-$B22-$C22)+AT22 | AV22: =AU22*$AV$4*(1-$B22-$C22)+AU22 | AW22: =AV22*$AW$4*(1-$B22-$C22)+AV22 | AX22: =AW22*$AX$4*(1-$B22-$C22)+AW22 | AY22: =AX22*$AY$4*(1-$B22-$C22)+AX22 | AZ22: =AY22*$AZ$4*(1-$B22-$C22)+AY22 | BA22: =AZ22*$BA$4*(1-$B22-$C22)+AZ22 | BB22: =BA22*BB$4*(1-$B22-$C22)+BA22+SUMIFS(Investments!$D:$D,Investments!$B:$B,$A22,Investments!$C:$C,"BTC",Investments!$A:$A,BB$8) | BC22: =BB22*BC$4*(1-$B22-$C22)+BB22+SUMIFS(Investments!$D:$D,Investments!$B:$B,$A22,Investments!$C:$C,"BTC",Investments!$A:$A,BC$8) | BD22: =BC22*BD$4*(1-$B22-$C22)+BC22+SUMIFS(Investments!$D:$D,Investments!$B:$B,$A22,Investments!$C:$C,"BTC",Investments!$A:$A,BD$8) | BE22: =BD22*BE$4*(1-$B22-$C22)+BD22+SUMIFS(Investments!$D:$D,Investments!$B:$B,$A22,Investments!$C:$C,"BTC",Investments!$A:$A,BE$8) | BF22: =BE22*BF$4*(1-$B22-$C22)+BE22+SUMIFS(Investments!$D:$D,Investments!$B:$B,$A22,Investments!$C:$C,"BTC",Investments!$A:$A,BF$8)
